Workbook

Sheet Balance Sheet
A1: Consolidated Balance Sheet (in millions of CHF) (Nestle, 2025; Nestle, 2024; Nestle, 2023; Nestle, 2022; Nestle, 2021; Nestle, 2020)
A4: Particulars | C4: 2024 | D4: 2023 | E4: 2022 | F4: 2021 | G4: 2020 | H4: 2019
A6: Assets
B7: Current Assets
B8: Cash and cash equivalents | C8: 5556 | D8: 4816 | E8: 5511 | F8: 6988 | G8: 5235 | H8: 7469
B9: Short-Terms Investments | C9: 2315 | D9: 1035 | E9: 1176 | F9: 7007 | G9: 3374 | H9: 2794
B10: Inventories | C10: 13260 | D10: 11896 | E10: 15019 | F10: 11982 | G10: 10101 | H10: 9343
B11: Trade and Other Receivables | C11: 11251 | D11: 10995 | E11: 11116 | F11: 11155 | G11: 10746 | H11: 11766
B12: Prepayments | C12: 543 | D12: 521 | E12: 549 | F12: 575 | G12: 477 | H12: 498
B13: Derivative assets | C13: 792 | D13: 278 | E13: 309 | F13: 278 | G13: 310 | H13: 254
B14: Current income tax assets | C14: 1334 | D14: 1284 | E14: 1285 | F14: 1204 | G14: 708 | H14: 768
B15: Assets held for sale | C15: 137 | D15: 32 | E15: 97 | F15: 68 | G15: 3117 | H15: 2771
B16: Total Current Assets | C16: =SUM(C8:C15) -> 35188 | D16: =SUM(D8:D15) -> 30857 | E16: =SUM(E8:E15) -> 35062 | F16: =SUM(F8:F15) -> 39257 | G16: =SUM(G8:G15) -> 34068 | H16: =SUM(H8:H15) -> 35663
B18: Non Current Assets
B19: Property, plant and equipment | C19: 33706 | D19: 30467 | E19: 30141 | F19: 28345 | G19: 25840 | H19: 28762
B20: Goodwill | C20: 30595 | D20: 28693 | E20: 31262 | F20: 31012 | G20: 27620 | H20: 28896
B21: Intangible assets | C21: 19245 | D21: 18225 | E21: 20237 | F21: 22223 | G21: 20148 | H21: 17824
B22: Investments in associates and joint ventures | C22: 14326 | D22: 13088 | E22: 13023 | F22: 11806 | G22: 12005 | H22: 11505
B23: Financial assets | C23: 3650 | D23: 2947 | E23: 3253 | F23: 2824 | G23: 2594 | H23: 2611
B24: Derivative assets | C24: 84 | D24: 130 | E24: 0 | F24: 0 | G24: 0
B25: Employee Benefits Assets and Reimbursement Rights | C25: 1475 | D25: 962 | E25: 1161 | F25: 2417 | G25: 468 | H25: 510
B26: Current income tax assets | C26: 0 | D26: 0 | E26: 0 | F26: 0 | G26: 0 | H26: 55
B27: Deferred Tax Assets | C27: 995 | D27: 1181 | E27: 1043 | F27: 1258 | G27: 1285 | H27: 2114
B28: Total Non Current Assets | C28: =SUM(C19:C27) -> 104076 | D28: =SUM(D19:D27) -> 95693 | E28: =SUM(E19:E27) -> 100120 | F28: =SUM(F19:F27) -> 99885 | G28: =SUM(G19:G27) -> 89960 | H28: =SUM(H19:H27) -> 92277
A30: Total Assets | C30: =C16+C28 -> 139264 | D30: =D16+D28 -> 126550 | E30: =E16+E28 -> 135182 | F30: =F16+F28 -> 139142 | G30: =G16+G28 -> 124028 | H30: =H16+H28 -> 127940
A33: Liabilities and equity
B34: Current Liabilities
B35: Financial debt | C35: 11863 | D35: 9416 | E35: 10892 | F35: 10092 | G35: 12019 | H35: 14032
B36: Derivative liabilities | C36: 408 | D36: 317 | E36: 352 | F36: 464 | G36: 18515 | H36: 18803
B37: Trade and other payables | C37: 21807 | D37: 19204 | E37: 20523 | F37: 20907 | G37: 4917 | H37: 4492
B38: Accruals | C38: 5466 | D38: 5112 | E38: 5114 | F38: 5051 | G38: 508 | H38: 802
B39: Provisions | C39: 865 | D39: 675 | E39: 620 | F39: 532 | G39: 254 | H39: 420
B40: Current income tax liabilities | C40: 2435 | D40: 2360 | E40: 2447 | F40: 2962 | G40: 2661 | H40: 2673
B41: Liabilities directly associatecl with assets held for sale | C41: 19 | D41: 0 | E41: 28 | F41: 12 | G41: 848 | H41: 393
B42: Total Current Liabilities | C42: =SUM(C35:C41) -> 42863 | D42: =SUM(D35:D41) -> 37084 | E42: =SUM(E35:E41) -> 39976 | F42: =SUM(F35:F41) -> 40020 | G42: =SUM(G35:G41) -> 39722 | H42: =SUM(H35:H41) -> 41615
B44: Non-Current Liabilities
B45: Financial debt | C45: 51697 | D45: 45825 | E45: 43420 | F45: 36482 | G45: 27928 | H45: 23132
B46: Derivative liabilities | C46: 307 | D46: 239 | E46: 470 | F46: 0 | G46: 0 | H46: 0
B47: Employee benefits liabilities | C47: 2629 | D47: 2718 | E47: 2884 | F47: 3779 | G47: 5118 | H47: 6151
B48: Provisions | C48: 1086 | D48: 1303 | E48: 1113 | F48: 1106 | G48: 1029 | H48: 1162
...

Sheet Profit and Loss
A1: Consolidated Profit and Loss (in millions of CHF) (Nestle, 2025; Nestle, 2024; Nestle, 2023; Nestle, 2022; Nestle, 2021; Nestle, 2020)
A3: Particulars | C3: 2024 | D3: 2023 | E3: 2022 | F3: 2021 | G3: 2020 | H3: 2019
B4: Sales | C4: 91354 | D4: 92998 | E4: 94424 | F4: 87088 | G4: 84343 | H4: 92568
B5: Other revenue | C5: 366 | D5: 353 | E5: 356 | F5: 382 | G5: 338 | H5: 297
B6: Cost of goods sold | C6: -48670 | D6: -50328 | E6: -51745 | F6: -45468 | G6: -42971 | H6: -46647
B7: Distribution expenses | C7: -7567 | D7: -7765 | E7: -8386 | F7: -7919 | G7: -7861 | H7: -8496
B8: Marketing ancl administration expenses | C8: -18112 | D8: -17549 | E8: -16850 | F8: -17294 | G8: -17370 | H8: -19790
B9: Research ancl development costs | C9: -1667 | D9: -1656 | E9: -1696 | F9: -1670 | G9: -1576 | H9: -1672
B10: Other trading income | C10: 124 | D10: 132 | E10: 107 | F10: 171 | G10: 238 | H10: 163
B11: Other trading expenses | C11: -1195 | D11: -1665 | E11: -3015 | F11: -3131 | G11: -908 | H11: -2749
B12: Trading Operating Profit/ Gross Profit | C12: =SUM(C4:C11) -> 14633 | D12: =SUM(D4:D11) -> 14520 | E12: =SUM(E4:E11) -> 13195 | F12: =SUM(F4:F11) -> 12159 | G12: =SUM(G4:G11) -> 14233 | H12: =SUM(H4:H11) -> 13674
B13: Other operating income | C13: 474 | D13: 298 | E13: 340 | F13: 698 | G13: 1919 | H13: 3717
B14: Other operating expenses | C14: -383 | D14: -755 | E14: -1209 | F14: -1178 | G14: -1356 | H14: -1313
B15: Operating profit / Earnings Before Interest and Tax | C15: =SUM(C12:C14) -> 14724 | D15: =SUM(D12:D14) -> 14063 | E15: =SUM(E12:E14) -> 12326 | F15: =SUM(F12:F14) -> 11679 | G15: =SUM(G12:G14) -> 14796 | H15: =SUM(H12:H14) -> 16078
B16: Financial Income | C16: 358 | D16: 284 | E16: 210 | F16: 80 | G16: 109 | H16: 200
B17: Financial Expense | C17: -1843 | D17: -1644 | E17: -1250 | F17: -953 | G17: -983 | H17: -1216
B18: Income from associates and joint ventures | C18: 1249 | D18: 1120 | E18: 1040 | F18: 8651 | G18: 1815 | H18: 1001
B19: Earnings before Tax | C19: =SUM(C15:C18) -> 14488 | D19: =SUM(D15:D18) -> 13823 | E19: =SUM(E15:E18) -> 12326 | F19: =SUM(F15:F18) -> 19457 | G19: =SUM(G15:G18) -> 15737 | H19: =SUM(H15:H18) -> 16063
B20: Taxes | C20: -3314 | D20: -2314 | E20: -2730 | F20: -2261 | G20: -3365 | H20: -3159
B21: Earnings after Tax | C21: =SUM(C19:C20) -> 11174 | D21: =SUM(D19:D20) -> 11509 | E21: =SUM(E19:E20) -> 9596 | F21: =SUM(F19:F20) -> 17196 | G21: =SUM(G19:G20) -> 12372 | H21: =SUM(H19:H20) -> 12904
B23: Minority Share | C23: 290 | D23: 300 | E23: 326 | F23: 291 | G23: 140 | H23: 295
B24: Net Profit to Shareholders | C24: =C21-C23 -> 10884 | D24: =D21-D23 -> 11209 | E24: =E21-E23 -> 9270 | F24: =F21-F23 -> 16905 | G24: =G21-G23 -> 12232 | H24: =H21-H23 -> 12609
B27: EPS | C27: =C24/'Balance Sheet'!C72 -> 4.192604 | D27: =D24/'Balance Sheet'!D72 -> 4.2362056 | E27: =E24/'Balance Sheet'!E72 -> 3.4244551 | F27: =F24/'Balance Sheet'!F72 -> 6.0634864 | G27: =G24/'Balance Sheet'!G72 -> 4.2994728 | H27: =H24/'Balance Sheet'!H72 -> 4.3048822
B28: DPS | C28: 3.05 | D28: 3 | E28: 2.95 | F28: 2.8 | G28: 2.75
B29: MP | C29: 74.88 | D29: 97.51 | E29: 107.41 | F29: 127.44 | G29: 104.26
B31: The instrinsic value as per Refinitiv database is 72.89. so the nestle shares are over valued slightly.
B32: Nestle is value firm and that it provides consistent dividends.

Sheet Cash Flow
A1: Company Fundamentals - Cash Flow
A2: Company Name | B2: Nestle SA (NESN.S)
A3: Country of Exchange | B3: Switzerland
A4: TRBC Industry Group | B4: Food & Tobacco
A5: Particulars (Nestle, 2025; Nestle, 2024; Nestle, 2023; Nestle, 2022; Nestle, 2021; Nestle, 2020) | B5: 31-12-2024 | C5: 31-12-2023 | D5: 31-12-2022 | E5: 31-12-2021 | F5: 31-12-2020
A6: Operating Cash Flow - Indirect
A7: Profit/(Loss) - Starting Line - Cash Flow | B7: 11174 | C7: 11509 | D7: 9596 | E7: 17196 | F7: 12372
A8: Non-cash Items & Reconciliation Adjustments - Cash Flow | B8: 7545 | C8: 6962 | D8: 9292 | E8: 700 | F8: 5774
A9: Equity Income/(Loss) in Net Earnings - Cash Flow - to Reconcile | B9: -1249 | C9: -1120 | D9: -1040 | E9: -8651 | F9: -1815
A10: Income Tax Expense - Cash Flow - to Reconcile | B10: 3314 | C10: 2314 | D10: 2730 | E10: 2261 | F10: 3365
A11: Financial Income/(Expense) - Cash Flow - to Reconcile | B11: 1485 | C11: 1360 | D11: 1040 | E11: 873 | F11: 874
A12: Other Non-Cash Items & Reconciliation Adjustments - Cash Flow - to Reconcile | B12: -340 | C12: -71 | D12: 99 | E12: 351 | F12: 814
A13: Depreciation, Depletion & Amortization including Impairment - Cash Flow - to Reconcile | B13: 4162 | C13: 4105 | D13: 6267 | E13: 6054 | F13: 4176
A14: Depreciation & Depletion - Property, Plant & Equipment - Cash Flow - to Reconcile | B14: 3110 | C14: 2993 | D14: 3097 | E14: 3056 | F14: 3127
A15: Impairment - Property, Plant & Equipment including Intangible Assets - Cash Flow - to Reconcile | B15: 580 | C15: 647 | D15: 2726 | E15: 2614 | F15: 711
A16: Amortization - Intangible Assets & Deferred Charges - Cash Flow - to Reconcile | B16: 472 | C16: 465 | D16: 444 | E16: 384 | F16: 338
A17: Assets Sale - Gain/(Loss) - Cash Flow - to Reconcile | B17: 57 | C17: 232 | D17: 68 | E17: -318 | F17: -1763
A18: Share Based Payments - Cash Flow - to Reconcile | B18: 116 | C18: 142 | D18: 128 | E18: 130 | F18: 123
... A31: Net Cash Flow from Operating Activities | B31: 16675 | C31: 15941 | D31: 11907 | E31: 13864 | F31: 14377
A32: Investing Cash Flow
A33: Capital Expenditures - Net - Cash Flow | B33: 5963 | C33: 6203 | D33: 5361 | E33: 5341 | F33: 4364
A34: Property, Plant & Equipment - Purchased/(Sold) - Net - Cash Flow | B34: 5638 | C34: 5714 | D34: 5095 | E34: 4880 | F34: 4076
A35: Property, Plant & Equipment - Purchased - Cash Flow | B35: 5638 | C35: 5714 | D35: 5095 | E35: 4880 | F35: 4076
A36: Intangible Assets - Purchased/(Sold) - Net - Total - Cash Flow | B36: 325 | C36: 489 | D36: 266 | E36: 461 | F36: 288
A37: Intangible Assets - Purchased/Acquired - Cash Flow | B37: 325 | C37: 489 | D37: 266 | E37: 461 | F37: 288
A38: Capital Expenditures - Total | B38: 5963 | C38: 6203 | D38: 5361 | E38: 5341 | F38: 4364
A39: Acquisition & Disposals of Business - Assets - Sold/(Acquired) - Net - Cash Flow | B39: -832 | C39: 4 | D39: -1550 | E39: -2864 | F39: -604
A40: Acquisition of Business - Cash Flow | B40: 832 | C40: 211 | D40: 1710 | E40: 6394 | F40: 4520
A41: Business - Sold - Cash Flow | C41: 215 | D41: 160 | E41: 3530 | F41: 3916
A42: Investments excluding Loans - Decrease/(Increase) - Cash Flow | B42: -1251 | C42: -80 | D42: 5902 | E42: -3610 | F42: -749
A43: Investment Securities - Unclassified - Sold/(Purchased) - Net - Total - Cash Flow | B43: -1251 | C43: -80 | D43: 5902 | E43: -3610 | F43: -749
A44: Investments - Associated Companies & Joint Ventures - Sold/(Purchased) - Cash Flow | B44: -532 | C44: -582 | D44: -918 | E44: 8579 | F44: -182
A45: Other Investing Cash Flow - Decrease/(Increase) | B45: -46 | C45: 665 | D45: 24 | E45: 192 | F45: 232
A46: Net Cash Flow from Investing Activities | B46: -8624 | C46: -6196 | D46: -1903 | E46: -3044 | F46: -5667
A47: Financing Cash Flow
A48: Dividends Paid - Cash - Total - Cash Flow | B48: 7816 | C48: 7829 | D48: 7618 | E48: 7681 | F48: 7700
A49: Dividends - Common - Cash Paid | B49: 7816 | C49: 7829 | D49: 7618 | E49: 7681 | F49: 7700
A50: Stock - Total - Issuance/(Retirement) - Net - Cash Flow | B50: -4678 | C50: -5234 | D50: -10679 | E50: -6548 | F50: -6814
A51: Stock - Issuance/(Retirement) - Net - Excluding Options/Warrants - Cash Flow | B51: -4678 | C51: -5234 | D51: -10679 | E51: -6548 | F51: -6814
A52: Stock - Common - Issuance/(Retirement) - Net - Cash Flow | B52: -4678 | C52: -5234 | D52: -10679 | E52: -6548 | F52: -6814
...

Sheet Charts
A1: Current Ratio
A3: Year | B3: Current Assets | C3: Cash and Cash Equivalents | D3: Inventory | E3: Current Liabilities | F3: Current Ratio | G3: Quick Ratio | H3: Cash Ratio
A4: 2020 | B4: ='Balance Sheet'!G16 -> 34068 | C4: ='Balance Sheet'!G8 -> 5235 | D4: ='Balance Sheet'!G10 -> 10101 | E4: ='Balance Sheet'!G42 -> 39722 | F4: =B4/E4 -> 0.85766074 | G4: =(B4-D4)/E4 -> 0.60336841 | H4: =C4/E4 -> 0.13179095
A5: 2021 | B5: ='Balance Sheet'!F16 -> 39257 | C5: ='Balance Sheet'!F8 -> 6988 | D5: ='Balance Sheet'!F10 -> 11982 | E5: ='Balance Sheet'!F42 -> 40020 | F5: =B5/E5 -> 0.98093453 | G5: =(B5-D5)/E5 -> 0.68153423 | H5: =C5/E5 -> 0.17461269
A6: 2022 | B6: ='Balance Sheet'!E16 -> 35062 | C6: ='Balance Sheet'!E8 -> 5511 | D6: ='Balance Sheet'!E10 -> 15019 | E6: ='Balance Sheet'!E42 -> 39976 | F6: =B6/E6 -> 0.87707625 | G6: =(B6-D6)/E6 -> 0.50137583 | H6: =C6/E6 -> 0.13785771
A7: 2023 | B7: ='Balance Sheet'!D16 -> 30857 | C7: ='Balance Sheet'!D8 -> 4816 | D7: ='Balance Sheet'!D10 -> 11896 | E7: ='Balance Sheet'!D42 -> 37084 | F7: =B7/E7 -> 0.83208392 | G7: =(B7-D7)/E7 -> 0.51129867 | H7: =C7/E7 -> 0.12986733
A8: 2024 | B8: ='Balance Sheet'!C16 -> 35188 | C8: ='Balance Sheet'!C8 -> 5556 | D8: ='Balance Sheet'!C10 -> 13260 | E8: ='Balance Sheet'!C42 -> 42863 | F8: =B8/E8 -> 0.82094114 | G8: =(B8-D8)/E8 -> 0.51158342 | H8: =C8/E8 -> 0.12962228
A11: Quick Ratio
A13: Year | B13: Current Assets - Inventory | C13: Current Liabilities | D13: quick ratio
A14: 2020 | B14: ='Balance Sheet'!G16-'Balance Sheet'!G10 -> 23967 | C14: ='Balance Sheet'!G42 -> 39722 | D14: =B14/C14 -> 0.60336841
A15: 2021 | B15: ='Balance Sheet'!F16-'Balance Sheet'!F10 -> 27275 | C15: ='Balance Sheet'!F42 -> 40020 | D15: =B15/C15 -> 0.68153423
A16: 2022 | B16: ='Balance Sheet'!E16-'Balance Sheet'!E10 -> 20043 | C16: ='Balance Sheet'!E42 -> 39976 | D16: =B16/C16 -> 0.50137583
A17: 2023 | B17: ='Balance Sheet'!D16-'Balance Sheet'!D10 -> 18961 | C17: ='Balance Sheet'!D42 -> 37084 | D17: =B17/C17 -> 0.51129867
A18: 2024 | B18: ='Balance Sheet'!C16-'Balance Sheet'!C10 -> 21928 | C18: ='Balance Sheet'!C42 -> 42863 | D18: =B18/C18 -> 0.51158342
A21: Cash Ratio
A22: Year | B22: cash& cash Flow | C22: Current Liabilities | D22: Cash Ratio
A23: 2020 | B23: ='Balance Sheet'!G8 -> 5235 | C23: ='Balance Sheet'!G42 -> 39722 | D23: =B23/C23 -> 0.13179095
A24: 2021 | B24: ='Balance Sheet'!F8 -> 6988 | C24: ='Balance Sheet'!F42 -> 40020 | D24: =B24/C24 -> 0.17461269
A25: 2022 | B25: ='Balance Sheet'!E8 -> 5511 | C25: ='Balance Sheet'!E42 -> 39976 | D25: =B25/C25 -> 0.13785771
A26: 2023 | B26: ='Balance Sheet'!D8 -> 4816 | C26: ='Balance Sheet'!D42 -> 37084 | D26: =B26/C26 -> 0.12986733
A27: 2024 | B27: ='Balance Sheet'!C8 -> 5556 | C27: ='Balance Sheet'!C42 -> 42863 | D27: =B27/C27 -> 0.12962228
A30: Debt to Equity
A31: Year | B31: total debt | C31: total equity | D31: D O E
A32: 2020 | B32: =('Balance Sheet'!G35+'Balance Sheet'!G45) -> 39947 | C32: ='Balance Sheet'!G63 -> 46514 | D32: =B32/C32 -> 0.8588167
A33: 2021 | B33: =('Balance Sheet'!F35+'Balance Sheet'!F45) -> 46574 | C33: ='Balance Sheet'!F63 -> 53727 | D33: =B33/C33 -> 0.86686396
A34: 2022 | B34: =('Balance Sheet'!E35+'Balance Sheet'!E45) -> 54312 | C34: ='Balance Sheet'!E63 -> 42792 | D34: =B34/C34 -> 1.2692092
A35: 2023 | B35: =('Balance Sheet'!D35+'Balance Sheet'!D45) -> 55241 | C35: ='Balance Sheet'!D63 -> 36387 | D35: =B35/C35 -> 1.5181521
A36: 2024 | B36: =('Balance Sheet'!C35+'Balance Sheet'!C45) -> 63560 | C36: ='Balance Sheet'!C63 -> 36693 | D36: =B36/C36 -> 1.7322105
A39: asset T/O ratio
A40: Year | B40: SALES | C40: total asset | D40: Asset T/O Ratio
A41: 2020 | B41: ='Profit and Loss'!G4 -> 84343 | C41: ='Balance Sheet'!G30 -> 124028 | D41: =B41/C41 -> 0.68003193
A42: 2021 | B42: ='Profit and Loss'!F4 -> 87088 | C42: ='Balance Sheet'!F30 -> 139142 | D42: =B42/C42 -> 0.62589297
A43: 2022 | B43: ='Profit and Loss'!E4 -> 94424 | C43: ='Balance Sheet'!E30 -> 135182 | D43: =B43/C43 -> 0.69849536
A44: 2023 | B44: ='Profit and Loss'!D4 -> 92998 | C44: ='Balance Sheet'!D30 -> 126550 | D44: =B44/C44 -> 0.73487159
A45: 2024 | B45: ='Profit and Loss'!C4 -> 91354 | C45: ='Balance Sheet'!C30 -> 139264 | D45: =B45/C45 -> 0.65597714
A47: inventory T/o ratio
A48: Year | B48: cost of good sold | C48: avg inventory | D48: Inventory T/O Ratio
A49: 2020 | B49: =ABS('Profit and Loss'!G6) -> 42971 | C49: ='Balance Sheet'!G10+'Balance Sheet'!H10 -> 19444 | D49: =B49/C49 -> 2.2099877
A50: 2021 | B50: =ABS('Profit and Loss'!F6) -> 45468 | C50: ='Balance Sheet'!F10+'Balance Sheet'!G10 -> 22083 | D50: =B50/C50 -> 2.0589594
A51: 2022 | B51: =ABS('Profit and Loss'!E6) -> 51745 | C51: ='Balance Sheet'!E10+'Balance Sheet'!F10 -> 27001 | D51: =B51/C51 -> 1.9164105
...

Sheet analysis
A2: Liquidity Ratios
A3: Current Ratio | B3: The current ratio of Nestle is below 1. A current ratio below 1 is indicative of liquidity risk. However for Nestle, it is a deliberate strategy. By increasing the credit term and distributing cash balances in the form of dividend and buybacks, Nestle maintains a lean Working Capital. This finances Nestle's operations at no extra cost. Thus a low Current ratio is not a risk for Nestle but a part of its strategy
A4: Quick Ratio | B4: quick ratio is lower than the current ratio, signaling a significant share of current assets is inventory. Nestle holds low balances of current assets over current liabilities as part of its startegy to maintain a lean working capital.
A5: Cash Ratio | B5: Too much free cash is unutilised capital and also makes the balance sheet look heavier. Nestle operating cash flow is robust and predictable reduceing the need for large cash reserves to absorb shock. This can be seen in the way Nestle maintained its dividend outflows during and shortly after the Covid period reinforcing its image as a reliable value firm
A6: overall | B6: Nestle maintains lower levels of Current assets over Current Liabilities. The major component of Current Assets is Inventories. Nestle maintints higher levels of current liabilities especially their trade creditors using favourable terms of credit to finance their operations at near zero cost. This indicative of efficient working caoital management. Nestle also does not need high cash reseves du to its stong business model and giving it consistent cash flows. Therefore it distributes its high cash balances as dividends and buybacks to signal future cash flows to maintain a reputation a low risk firm and improve its EPS.
A8: Leverage Ratios
A9: Debt to Equity | B9: The debt-to-equity ratio increased from from 0.87 (2020) to 1.73 (2024). This reflects the increasing role of debt in financing operations. When Share buyback is also taken into account, it means debt is replacing equity while maintaining total capital. This helps to boost EPS and increases its market valuation however this also increases financial risk due to rising interest costs. This decreases Nestle's ability to be flexible about its capital deployment during adverse market scenarios
A12: Efficiency Ratios
A13: Asset T/O Ratio | B13: The asset t/o ratio remain stable throughout the review period with modest fluctuations. The ratio fell in 2024 which is coinciding with fall in sales due to changes in market demand
A14: Inventory T/O Ratio | B14: The inventory t/o ratio seems to be falling from 2.21 (2020) to 1.87 (2023). This is reflected of the fact that Covid 19 has changed consumption patterns which is making it difficult to products leading to buildup of stocks. However the ratio improved to 1.93 (2024) showing that inventory started moving faster possibly due to post Covid Normalisation
A17: Profitibility Ratios
A18: GP Ratio | B18: GP% fell in 2021, cost inflation (raw materials), discounting, or mix shift to lower margin products. 2021 to 2024 (gradual rise to 16.02%): Improved gross margin due to return to pre covid levels. The 2024 GP% shows that the company regained margin on 2024. The fall in 2021 is due to effect of Covid
A19: NP Ratio | B19: NP% falls the GP% for the most part except 2021. The fall in NP in 2021 and its subsequent increase in margin is normalisation to pre covid levels. 2021 recorded exceptionally high net profit due to non operating profit on the disposal on L Oreal shares and is not part of its operations. The profit on disposal was used to fund buyback of its shares
A20: Return on Equity | B20: Nestle's ROE has been stable for the most part showcasing strong profit generation capability from the equity capital invested in the company The 2022 dip was due to lower net profit from Covid effects, howeve it is going back to pre covid normal levels | C20: …
A21: Return on Capital Employed | B21: ROCE fell in 2021 because the capital employed increased due to high retained earnings from the profits on disposal of L'Oreal shares. ROCE has been consistent for the most part with minor variations due to covid and change inconsumption pattern
A22: Return on Assets | B22: Peaked in 2021 due to strong net profit that year; big drop in 2022 (net profit fell while assets stayed high). The ratio is stabilising to normal levels due to post covid normalisation. Overall Nestle has good profit generation capacity from its assets both tangible and imtangible assets
A25: Valuation Ratios
A26: EPS | B26: EPS peaked in 2021 due to high net profit obtained from disposal of L'Oreal share in 2022. EPS stabilised in 2022 after buyback and is consistent with pre-Covid levels. This plays a huge rolein their Dividend startegy as well
A27: DPS | B27: Nestle maintain its dividend payout ratio in absolute terms as it wants to maintain itself defensive cash rich FMCG that values its equity holders. Therefore Nestle never cuts dividends over short term fluctuations in profitability. It is also using its buyback strategy to both reduce effect of certain Investments on its overall Balance sheet thus increasing EPS and simulatenously using it to reward shareholders. It strategically uses timing effect to accelerate and decelerate buyback as and when reqired to maintain consistency in DPS. Nestle is a huge market player with significant market influence. Big Insitutional investors like Sovereign Wealth Funds and Pension Funds invest in it. They depend on regular consistent Dividends to run their programmes. Hence Nestle uses its DPS strategy to maintain its position as a low risk firm with consistent income which appels to risk averse long term investors.
A28: P/E Ratio | B28: The PE ratio is falling YOY while EPS remains constant indicated that investors are not very optimistic about future growth of Nestle. This is consistent with overall industry experiencing lower demand due to consumers shifting to private branded goods and changing overall consumption patterns. The EPS is constant however fall in sales, rising input and associated costs and indicates that the EPS is being maintained through non operational activities.
A29: Market Value/ Book Value | B29: The market value to book value is falling due to multiple factors like falling sales and other financial indicators as well as governance issues like CEO beimg changed which reduced customer confidence in the firm which is reflected in the prices
A32: Operating Leverage | B32: Nestle low operating leverage means that it has more of variable costs than fixed costs. Hence profitability is dependant more on cost management and that operating profit closely follows growth in sales
A33: Financial Leverage | B33: Nestle's Financial Leverage is increasing means that interest payments are increasing. This is consistent with growth in debt in the capital structure of Nestle. But a rising Financial leverage indicates that debt is eating into Nestle's ability to convert revenue and operating profits into taxable profits. If the interest expense grows too large, then it ends up affecting the profit availble to shareholders
A34: Combined Leverage | B34: Nestle Combined Leverage is indicative that while Nestle is reducing its operational risk but has increased its financial risk by replacing equity with debt as ovserved from rising debt and buyback programmes. This increases Nestle's Valuation provided it can manage its debt related costs.

Sheet Liquidity Ratios
A1: Liquidity Ratios
A3: Current Ratio | B3: The current ratio of Nestle is below 1. A current ratio below 1 is indicative of liquidity risk. However for Nestle, it is a deliberate strategy. By increasing the credit term and distributing cash balances in the form of dividend and buybacks, Nestle maintains a lean Working Capital. This finances Nestle's operations at no extra cost. Thus a low Current ratio is not a risk for Nestle but a part of its strategy
A4: Quick Ratio | B4: quick ratio is lower than the current ratio, signaling a significant share of current assets is inventory. Nestle holds low balances of current assets over current liabilities as part of its startegy to maintain a lean working capital.
A5: Cash Ratio | B5: Too much free cash is unutilised capital and also makes the balance sheet look heavier. Nestle operating cash flow is robust and predictable reduceing the need for large cash reserves to absorb shock. This can be seen in the way Nestle maintained its dividend outflows during and shortly after the Covid period reinforcing its image as a reliable value firm
A6: overall | B6: Nestle maintains lower levels of Current assets over Current Liabilities. The major component of Current Assets is Inventories. Nestle maintints higher levels of current liabilities especially their trade creditors using favourable terms of credit to finance their operations at near zero cost. This indicative of efficient working caoital management. Nestle also does not need high cash reseves du to its stong business model and giving it consistent cash flows. Therefore it distributes its high cash balances as dividends and buybacks to signal future cash flows to maintain a reputation a low risk firm and improve its EPS.
A8: Year | B8: Current Assets | C8: Cash and Cash Equivalents | D8: Inventory | E8: Current Liabilities | F8: Current Ratio | G8: Quick Ratio | H8: Cash Ratio
A9: 2020 | B9: ='Balance Sheet'!G16 -> 34068 | C9: ='Balance Sheet'!G8 -> 5235 | D9: ='Balance Sheet'!G10 -> 10101 | E9: ='Balance Sheet'!G42 -> 39722 | F9: =B9/E9 -> 0.85766074 | G9: =(B9-D9)/E9 -> 0.60336841 | H9: =C9/E9 -> 0.13179095
A10: 2021 | B10: ='Balance Sheet'!F16 -> 39257 | C10: ='Balance Sheet'!F8 -> 6988 | D10: ='Balance Sheet'!F10 -> 11982 | E10: ='Balance Sheet'!F42 -> 40020 | F10: =B10/E10 -> 0.98093453 | G10: =(B10-D10)/E10 -> 0.68153423 | H10: =C10/E10 -> 0.17461269
A11: 2022 | B11: ='Balance Sheet'!E16 -> 35062 | C11: ='Balance Sheet'!E8 -> 5511 | D11: ='Balance Sheet'!E10 -> 15019 | E11: ='Balance Sheet'!E42 -> 39976 | F11: =B11/E11 -> 0.87707625 | G11: =(B11-D11)/E11 -> 0.50137583 | H11: =C11/E11 -> 0.13785771
A12: 2023 | B12: ='Balance Sheet'!D16 -> 30857 | C12: ='Balance Sheet'!D8 -> 4816 | D12: ='Balance Sheet'!D10 -> 11896 | E12: ='Balance Sheet'!D42 -> 37084 | F12: =B12/E12 -> 0.83208392 | G12: =(B12-D12)/E12 -> 0.51129867 | H12: =C12/E12 -> 0.12986733
A13: 2024 | B13: ='Balance Sheet'!C16 -> 35188 | C13: ='Balance Sheet'!C8 -> 5556 | D13: ='Balance Sheet'!C10 -> 13260 | E13: ='Balance Sheet'!C42 -> 42863 | F13: =B13/E13 -> 0.82094114 | G13: =(B13-D13)/E13 -> 0.51158342 | H13: =C13/E13 -> 0.12962228

Sheet Debt to Equity
A1: Debt to Equity
B3: The debt-to-equity ratio increased from 0.87 (2020) to 1.73 (2024). This reflects the increasing role of debt in financing operations. When Share buyback is also taken into account, it means debt is replacing equity while maintaining total capital. This helps to boost EPS and increases its market valuation however this also increases financial risk due to rising interest costs. This decreases Nestle's ability to be flexible about its capital deployment during adverse market scenarios
A6: Year | B6: total debt | C6: total equity | D6: D O E
A7: 2020 | B7: =('Balance Sheet'!G35+'Balance Sheet'!G45) -> 39947 | C7: ='Balance Sheet'!G63 -> 46514 | D7: =B7/C7 -> 0.8588167
A8: 2021 | B8: =('Balance Sheet'!F35+'Balance Sheet'!F45) -> 46574 | C8: ='Balance Sheet'!F63 -> 53727 | D8: =B8/C8 -> 0.86686396
A9: 2022 | B9: =('Balance Sheet'!E35+'Balance Sheet'!E45) -> 54312 | C9: ='Balance Sheet'!E63 -> 42792 | D9: =B9/C9 -> 1.2692092
A10: 2023 | B10: =('Balance Sheet'!D35+'Balance Sheet'!D45) -> 55241 | C10: ='Balance Sheet'!D63 -> 36387 | D10: =B10/C10 -> 1.5181521
A11: 2024 | B11: =('Balance Sheet'!C35+'Balance Sheet'!C45) -> 63560 | C11: ='Balance Sheet'!C63 -> 36693 | D11: =B11/C11 -> 1.7322105

Sheet Leverage
A1: Leverage
A3: Operating Leverage | B3: Nestle low operating leverage means that it has more of variable costs than fixed costs. Hence profitability is dependant more on cost management and that operating profit closely follows growth in sales
A4: Financial Leverage | B4: Nestle's Financial Leverage is increasing means that interest payments are increasing. This is consistent with growth in debt in the capital structure of Nestle. But a rising Financial leverage indicates that debt is eating into Nestle's ability to convert revenue and operating profits into taxable profits. If the interest expense grows too large, then it ends up affecting the profit availble to shareholders
A5: Combined Leverage | B5: Nestle Combined Leverage is indicative that while Nestle is reducing its operational risk but has increased its financial risk by replacing equity with debt as ovserved from rising debt and buyback programmes. This increases Nestle's Valuation provided it can manage its debt related costs.
A10: EBIT
A11: year | B11: current year value | C11: previous year value | D11: % change in EBIT
A12: 2020 | B12: ='Profit and Loss'!G15 -> 14796 | C12: ='Profit and Loss'!H15 -> 16078 | D12: =(B12-C12)/C12 -> -0.079736286
A13: 2021 | B13: ='Profit and Loss'!F15 -> 11679 | C13: =B12 -> 14796 | D13: =(B13-C13)/C13 -> -0.21066504
A14: 2022 | B14: ='Profit and Loss'!E15 -> 12326 | C14: =B13 -> 11679 | D14: =(B14-C14)/C14 -> 0.055398579
A15: 2023 | B15: ='Profit and Loss'!D15 -> 14063 | C15: =B14 -> 12326 | D15: =(B15-C15)/C15 -> 0.14092163
A16: 2024 | B16: ='Profit and Loss'!C15 -> 14724 | C16: =B15 -> 14063 | D16: =(B16-C16)/C16 -> 0.047002773
A18: EBT
A19: YEAR | B19: current year value | C19: previous year value | D19: % EBT
A20: 2020 | B20: ='Profit and Loss'!G19 -> 15737 | C20: ='Profit and Loss'!H19 -> 16063 | D20: =(B20-C20)/C20 -> -0.020295088
A21: 2021 | B21: ='Profit and Loss'!F19 -> 19457 | C21: =B20 -> 15737 | D21: =(B21-C21)/C21 -> 0.23638559
A22: 2022 | B22: ='Profit and Loss'!E19 -> 12326 | C22: =B21 -> 19457 | D22: =(B22-C22)/C22 -> -0.36650049
A23: 2023 | B23: ='Profit and Loss'!D19 -> 13823 | C23: =B22 -> 12326 | D23: =(B23-C23)/C23 -> 0.12145059
A24: 2024 | B24: ='Profit and Loss'!C19 -> 14488 | C24: =B23 -> 13823 | D24: =(B24-C24)/C24 -> 0.048108225
A26: SALES
A27: YEAR | B27: current year value | C27: previous year value | D27: % SALES
A28: 2020 | B28: ='Profit and Loss'!G4 -> 84343 | C28: ='Profit and Loss'!H4 -> 92568 | D28: =(B28-C28)/C28 -> -0.0888536
A29: 2021 | B29: ='Profit and Loss'!F4 -> 87088 | C29: =B28 -> 84343 | D29: =(B29-C29)/C29 -> 0.032545677
A30: 2022 | B30: ='Profit and Loss'!E4 -> 94424 | C30: =B29 -> 87088 | D30: =(B30-C30)/C30 -> 0.084236634
A31: 2023 | B31: ='Profit and Loss'!D4 -> 92998 | C31: =B30 -> 94424 | D31: =(B31-C31)/C31 -> -0.015102093
A32: 2024 | B32: ='Profit and Loss'!C4 -> 91354 | C32: =B31 -> 92998 | D32: =(B32-C32)/C32 -> -0.0176778
A34: Leverages
A35: YEAR | B35: Sales | C35: EBIT% | D35: EBT% | E35: SALES% | F35: OL | G35: FL | H35: CL
A36: 2020 | B36: =B28 -> 84343 | C36: =D12 -> -0.079736286 | D36: =D20 -> -0.020295088 | E36: =D28 -> -0.0888536 | F36: =C36/E36 -> 0.89738948 | G36: =D36/C36 -> 0.25452763 | H36: =D36/E36 -> 0.22841042
A37: 2021 | B37: =B29 -> 87088 | C37: =D13 -> -0.21066504 | D37: =D21 -> 0.23638559 | E37: =D29 -> 0.032545677 | F37: =C37/E37 -> -6.4729041 | G37: =D37/C37 -> -1.1220921 | H37: =D37/E37 -> 7.2631948
A38: 2022 | B38: =B30 -> 94424 | C38: =D14 -> 0.055398579 | D38: =D22 -> -0.36650049 | E38: =D30 -> 0.084236634 | F38: =C38/E38 -> 0.65765423 | G38: =D38/C38 -> -6.615702 | H38: =D38/E38 -> -4.3508444
A39: 2023 | B39: =B31 -> 92998 | C39: =D15 -> 0.14092163 | D39: =D23 -> 0.12145059 | E39: =D31 -> -0.015102093 | F39: =C39/E39 -> -9.331265 | G39: =D39/C39 -> 0.86183074 | H39: =D39/E39 -> -8.0419711
A40: 2024 | B40: =B32 -> 91354 | C40: =D16 -> 0.047002773 | D40: =D24 -> 0.048108225 | E40: =D32 -> -0.0176778 | F40: =C40/E40 -> -2.6588588 | G40: =D40/C40 -> 1.0235189 | H40: =D40/E40 -> -2.7213922

Sheet Efficiency Ratios
A1: Effeciency Ratios
A3: Asset T/O Ratio | B3: The asset t/o ratio remain stable throughout the review period with modest fluctuations. The ratio fell in 2024 which is coinciding with fall in sales due to changes in market demand.
A4: Inventory T/O Ratio | B4: The inventory t/o ratio seems to be falling from 2.21 (2020) to 1.87 (2023). This is reflected of the fact that Covid 19 has changed consumption patterns which is making it difficult to products leading to buildup of stocks. However the ratio improved to 1.93 (2024) showing that inventory started moving faster possibly due to post Covid Normalisation
A7: Asset T/O ratio
A8: Year | B8: SALES | C8: total asset | D8: Asset T/O Ratio
A9: 2020 | B9: ='Profit and Loss'!G4 -> 84343 | C9: ='Balance Sheet'!G30 -> 124028 | D9: =B9/C9 -> 0.68003193
A10: 2021 | B10: ='Profit and Loss'!F4 -> 87088 | C10: ='Balance Sheet'!F30 -> 139142 | D10: =B10/C10 -> 0.62589297
A11: 2022 | B11: ='Profit and Loss'!E4 -> 94424 | C11: ='Balance Sheet'!E30 -> 135182 | D11: =B11/C11 -> 0.69849536
A12: 2023 | B12: ='Profit and Loss'!D4 -> 92998 | C12: ='Balance Sheet'!D30 -> 126550 | D12: =B12/C12 -> 0.73487159
A13: 2024 | B13: ='Profit and Loss'!C4 -> 91354 | C13: ='Balance Sheet'!C30 -> 139264 | D13: =B13/C13 -> 0.65597714
A15: Inventory T/o ratio
A16: Year | B16: cost of good sold | C16: avg inventory | D16: Inventory T/O Ratio
A17: 2020 | B17: =ABS('Profit and Loss'!G6) -> 42971 | C17: ='Balance Sheet'!G10+'Balance Sheet'!H10 -> 19444 | D17: =B17/C17 -> 2.2099877
A18: 2021 | B18: =ABS('Profit and Loss'!F6) -> 45468 | C18: ='Balance Sheet'!F10+'Balance Sheet'!G10 -> 22083 | D18: =B18/C18 -> 2.0589594
A19: 2022 | B19: =ABS('Profit and Loss'!E6) -> 51745 | C19: ='Balance Sheet'!E10+'Balance Sheet'!F10 -> 27001 | D19: =B19/C19 -> 1.9164105
A20: 2023 | B20: =ABS('Profit and Loss'!D6) -> 50328 | C20: ='Balance Sheet'!D10+'Balance Sheet'!E10 -> 26915 | D20: =B20/C20 -> 1.8698867
A21: 2024 | B21: =ABS('Profit and Loss'!C6) -> 48670 | C21: ='Balance Sheet'!C10+'Balance Sheet'!D10 -> 25156 | D21: =B21/C21 -> 1.9347273

Sheet Profitability Ratios
A1: Profitability Ratios
A3: GP Ratio | B3: Nestle’s GP margin fell in 2021 due cost due to the pandemic. 2021 to 2024 saw a gradual rise to 16.02% due to return to pre covid levels. The 2024 GP margin shows that the company regained pre covid margin signalling return to normal business environemnt
A4: NP Ratio | B4: NP% falls the GP% for the most part except 2021. The fall in NP in 2021 and its subsequent increase in margin is normalisation to pre covid levels. 2021 recorded exceptionally high net profit due to non operating profit on the disposal on L Oreal shares and is not part of its operations. The profit on disposal was used to fund buyback of its shares. . The Net Profit margin is yet to reach pre covid levels as there are factors other operations that governance issues that are bringing down overall net profit margin.
A7: GP Ratio
A8: Year | B8: gross profit | C8: netsales | D8: GP
A9: 2020 | B9: ='Profit and Loss'!G12 -> 14233 | C9: ='Profit and Loss'!G4 -> 84343 | D9: =B9/C9 -> 0.16875141
A10: 2021 | B10: ='Profit and Loss'!F12 -> 12159 | C10: ='Profit and Loss'!F4 -> 87088 | D10: =B10/C10 -> 0.1396174
A11: 2022 | B11: ='Profit and Loss'!E12 -> 13195 | C11: ='Profit and Loss'!E4 -> 94424 | D11: =B11/C11 -> 0.13974201
A12: 2023 | B12: ='Profit and Loss'!D12 -> 14520 | C12: ='Profit and Loss'!D4 -> 92998 | D12: =B12/C12 -> 0.15613239
A13: 2024 | B13: ='Profit and Loss'!C12 -> 14633 | C13: ='Profit and Loss'!C4 -> 91354 | D13: =B13/C13 -> 0.16017908
A16: NP Ratio
A17: Year | B17: EARNING AFTER TAX | C17: net sales | D17: NP
A18: 2020 | B18: ='Profit and Loss'!G21 -> 12372 | C18: ='Profit and Loss'!G4 -> 84343 | D18: =B18/C18 -> 0.14668674
A19: 2021 | B19: ='Profit and Loss'!F21 -> 17196 | C19: ='Profit and Loss'!F4 -> 87088 | D19: =B19/C19 -> 0.19745545
A20: 2022 | B20: ='Profit and Loss'!E21 -> 9596 | C20: ='Profit and Loss'!E4 -> 94424 | D20: =B20/C20 -> 0.10162671
A21: 2023 | B21: ='Profit and Loss'!D21 -> 11509 | C21: ='Profit and Loss'!D4 -> 92998 | D21: =B21/C21 -> 0.12375535
A22: 2024 | B22: ='Profit and Loss'!C21 -> 11174 | C22: ='Profit and Loss'!C4 -> 91354 | D22: =B22/C22 -> 0.12231539

Sheet Returns
A1: Returns
A3: Return on Equity | B3: Nestle's ROE has been stable for the most part showcasing strong profit generation capability from the equity capital invested in the company The 2022 dip was due to lower net profit from Covid effects, howeve it is going back to pre covid normal levels
A4: Return on Capital Employed | B4: ROCE fell in 2021 because the capital employed increased due to high retained earnings from the profits on disposal of L'Oreal shares. ROCE has been consistent for the most part with minor variations due to covid and change inconsumption pattern
A5: Return on Assets | B5: Peaked in 2021 due to strong net profit that year; big drop in 2022 (net profit fell while assets stayed high). The ratio is stabilising to normal levels due to post covid normalisation. Overall Nestle has good profit generation capacity from its assets both tangible and imtangible assets
A8: Return on equity
A9: Year | B9: Reurn to Shareholders | C9: share holders equity | D9: ROE
A10: 2020 | B10: ='Profit and Loss'!G24 -> 12232 | C10: ='Balance Sheet'!G61 -> 45695 | D10: =B10/C10 -> 0.26768793
A11: 2021 | B11: ='Profit and Loss'!F24 -> 16905 | C11: ='Balance Sheet'!F61 -> 53140 | D11: =B11/C11 -> 0.31812194
A12: 2022 | B12: ='Profit and Loss'!E24 -> 9270 | C12: ='Balance Sheet'!E61 -> 41982 | D12: =B12/C12 -> 0.22080892
A13: 2023 | B13: ='Profit and Loss'!D24 -> 11209 | C13: ='Balance Sheet'!D61 -> 35742 | D13: =B13/C13 -> 0.31360864
A14: 2024 | B14: ='Profit and Loss'!C24 -> 10884 | C14: ='Balance Sheet'!C61 -> 35917 | D14: =B14/C14 -> 0.30303199
A16: Return on capital employed
A17: Year | B17: operating profit | C17: cap employed | D17: ROCE
A18: 2020 | B18: ='Profit and Loss'!G15 -> 14796 | C18: ='Balance Sheet'!G30-'Balance Sheet'!G42 -> 84306 | D18: =B18/C18 -> 0.17550352
A19: 2021 | B19: ='Profit and Loss'!F15 -> 11679 | C19: ='Balance Sheet'!F30-'Balance Sheet'!F42 -> 99122 | D19: =B19/C19 -> 0.1178245
A20: 2022 | B20: ='Profit and Loss'!E15 -> 12326 | C20: ='Balance Sheet'!E30-'Balance Sheet'!E42 -> 95206 | D20: =B20/C20 -> 0.12946663
A21: 2023 | B21: ='Profit and Loss'!D15 -> 14063 | C21: ='Balance Sheet'!D30-'Balance Sheet'!D42 -> 89466 | D21: =B21/C21 -> 0.15718821
A22: 2024 | B22: ='Profit and Loss'!C15 -> 14724 | C22: ='Balance Sheet'!C30-'Balance Sheet'!C42 -> 96401 | D22: =B22/C22 -> 0.152737
A24: Return on assets
A25: Year | B25: net profit | C25: total asset | D25: ROA
A26: 2020 | B26: ='Profit and Loss'!G24 -> 12232 | C26: ='Balance Sheet'!G30 -> 124028 | D26: =B26/C26 -> 0.098622892
A27: 2021 | B27: ='Profit and Loss'!F24 -> 16905 | C27: ='Balance Sheet'!F30 -> 139142 | D27: =B27/C27 -> 0.12149459
A28: 2022 | B28: ='Profit and Loss'!E24 -> 9270 | C28: ='Balance Sheet'!E30 -> 135182 | D28: =B28/C28 -> 0.068574218
A29: 2023 | B29: ='Profit and Loss'!D24 -> 11209 | C29: ='Balance Sheet'!D30 -> 126550 | D29: =B29/C29 -> 0.088573686
A30: 2024 | B30: ='Profit and Loss'!C24 -> 10884 | C30: ='Balance Sheet'!C30 -> 139264 | D30: =B30/C30 -> 0.078153722

Sheet Valuation
A1: Valuation
A3: EPS | B3: EPS peaked in 2021 due to high net profit obtained from disposal of L'Oreal share in 2022. EPS stabilised in 2022 after buyback and is consistent with pre-Covid levels. This plays a huge rolein their Dividend startegy as well
A4: DPS | B4: Nestle maintain its dividend payout ratio in absolute terms as it wants to maintain itself defensive cash rich FMCG that values its equity holders. Therefore Nestle never cuts dividends over short term fluctuations in profitability. It is also using its buyback strategy to both reduce effect of certain Investments on its overall Balance sheet thus increasing EPS and simulatenously using it to reward shareholders. It strategically uses timing effect to accelerate and decelerate buyback as and when reqired to maintain consistency in DPS. Nestle is a huge market player with significant market influence. Big Insitutional investors like Sovereign Wealth Funds and Pension Funds invest in it. They depend on regular consistent Dividends to run their programmes. Hence Nestle uses its DPS strategy to maintain its position as a low risk firm with consistent income which appels to risk averse long term investors.
A5: P/E Ratio | B5: The PE ratio is falling YOY while EPS remains constant indicated that investors are not very optimistic about future growth of Nestle. This is consistent with overall industry experiencing lower demand due to consumers shifting to private branded goods and changing overall consumption patterns. The EPS is constant however fall in sales, rising input and associated costs and indicates that the EPS is being maintained through non operational activities.
A6: Market Value/ Book Value | B6: The market value to book value was rising showing positive sentiment but it fell in 2024 due to multiple factors like falling sales as well as governance issues like CEO being fired for under performance which reduced customer confidence in the firm which is reflected in the prices and reduced P/E ratio and Market to Book Value
A8: Valuation | B8: The instrinsic value as per Refinitiv database is 72.92 as on 30/10/2025. so the nestle shares are over valued slightly. However considerig that Nestle is value firm and that it provides consistent dividends.
A11: Year | B11: net profit SH | C11: W.AVG.S.EPS | D11: EPS | E11: DPS | F11: Market Price | G11: P/E Ratio | H11: Market to Book Value
A12: 2020 | B12: ='Profit and Loss'!G24 -> 12232 | C12: ='Balance Sheet'!G72 -> 2845 | D12: =B12/C12 -> 4.2994728 | E12: 2.75 | F12: ='Profit and Loss'!G29 -> 104.26 | G12: =F12/D12 -> 24.249485 | H12: =$F12/(('Balance Sheet'!G$30-'Balance Sheet'!G$53)/'Balance Sheet'!G$70) -> 6.4576914
A13: 2021 | B13: ='Profit and Loss'!F24 -> 16905 | C13: ='Balance Sheet'!F73 -> 2791 | D13: =B13/C13 -> 6.0569688 | E13: 2.8 | F13: ='Profit and Loss'!F29 -> 127.44 | G13: =F13/D13 -> 21.040227 | H13: =$F13/(('Balance Sheet'!F$30-'Balance Sheet'!F$53)/'Balance Sheet'!F$70) -> 6.6771567
A14: 2022 | B14: ='Profit and Loss'!E24 -> 9270 | C14: ='Balance Sheet'!E73 -> 2709 | D14: =B14/C14 -> 3.4219269 | E14: 2.95 | F14: ='Profit and Loss'!E29 -> 107.41 | G14: =F14/D14 -> 31.388748 | H14: =$F14/(('Balance Sheet'!E$30-'Balance Sheet'!E$53)/'Balance Sheet'!E$70) -> 6.9026337
A15: 2023 | B15: ='Profit and Loss'!D24 -> 11209 | C15: ='Balance Sheet'!D73 -> 2648 | D15: =B15/C15 -> 4.233006 | E15: 3 | F15: ='Profit and Loss'!D29 -> 97.51 | G15: =F15/D15 -> 23.035639 | H15: =$F15/(('Balance Sheet'!D$30-'Balance Sheet'!D$53)/'Balance Sheet'!D$70) -> 7.1550746
A16: 2024 | B16: ='Profit and Loss'!C24 -> 10884 | C16: ='Balance Sheet'!C73 -> 2599 | D16: =B16/C16 -> 4.1877645 | E16: 3.05 | F16: ='Profit and Loss'!C29 -> 74.88 | G16: =F16/D16 -> 17.880662 | H16: =$F16/(('Balance Sheet'!C$30-'Balance Sheet'!C$53)/'Balance Sheet'!C$70) -> 5.3466765

Sheet Sum_Ratios
A1: Particulars | B1: 2024 | C1: 2023 | D1: 2022 | E1: 2021 | F1: 2020
A3: Liquidity Ratios
A4: Current Ratio | B4: =IFERROR('Balance Sheet'!C16/'Balance Sheet'!C42,"") -> 0.82094114 | C4: =IFERROR('Balance Sheet'!D16/'Balance Sheet'!D42,"") -> 0.83208392 | D4: =IFERROR('Balance Sheet'!E16/'Balance Sheet'!E42,"") -> 0.87707625 | E4: =IFERROR('Balance Sheet'!F16/'Balance Sheet'!F42,"") -> 0.98093453 | F4: =IFERROR('Balance Sheet'!G16/'Balance Sheet'!G42,"") -> 0.85766074 | H4: while the ideal current ratio is 2:1, Nestle maintains it a lower than 1 due to efficient working capital management represented by longer trade payables and lower levels of inventory.
A5: Quick Ratio | B5: =IFERROR(('Balance Sheet'!C16-'Balance Sheet'!C10)/'Balance Sheet'!C42,"") -> 0.51158342 | C5: =IFERROR(('Balance Sheet'!D16-'Balance Sheet'!D10)/'Balance Sheet'!D42,"") -> 0.51129867 | D5: =IFERROR(('Balance Sheet'!E16-'Balance Sheet'!E10)/'Balance Sheet'!E42,"") -> 0.50137583 | E5: =IFERROR(('Balance Sheet'!F16-'Balance Sheet'!F10)/'Balance Sheet'!F42,"") -> 0.68153423 | F5: =IFERROR(('Balance Sheet'!G16-'Balance Sheet'!G10)/'Balance Sheet'!G42,"") -> 0.60336841
A6: Cash Ratio | B6: =IFERROR('Balance Sheet'!C8/'Balance Sheet'!C42,"") -> 0.12962228 | C6: =IFERROR('Balance Sheet'!D8/'Balance Sheet'!D42,"") -> 0.12986733 | D6: =IFERROR('Balance Sheet'!E8/'Balance Sheet'!E42,"") -> 0.13785771 | E6: =IFERROR('Balance Sheet'!F8/'Balance Sheet'!F42,"") -> 0.17461269 | F6: =IFERROR('Balance Sheet'!G8/'Balance Sheet'!G42,"") -> 0.13179095 | H6: cash ratio falls in 2022, 2023 and 2024 primarily due to major share buyback programmes
A9: Leverage Ratios
A10: Debt to Equity | B10: =IFERROR(('Balance Sheet'!C35+'Balance Sheet'!C45)/'Balance Sheet'!C63,"") -> 1.7322105 | C10: =IFERROR(('Balance Sheet'!D35+'Balance Sheet'!D45)/'Balance Sheet'!D63,"") -> 1.5181521 | D10: =IFERROR(('Balance Sheet'!E35+'Balance Sheet'!E45)/'Balance Sheet'!E63,"") -> 1.2692092 | E10: =IFERROR(('Balance Sheet'!F35+'Balance Sheet'!F45)/'Balance Sheet'!F63,"") -> 0.86686396 | F10: =IFERROR(('Balance Sheet'!G35+'Balance Sheet'!G45)/'Balance Sheet'!G63,"") -> 0.8588167
A13: Efficiency Ratios
A14: Asset T/O Ratio | B14: =IFERROR('Profit and Loss'!C4/'Balance Sheet'!C30,"") -> 0.65597714 | C14: =IFERROR('Profit and Loss'!D4/'Balance Sheet'!D30,"") -> 0.73487159 | D14: =IFERROR('Profit and Loss'!E4/'Balance Sheet'!E30,"") -> 0.69849536 | E14: =IFERROR('Profit and Loss'!F4/'Balance Sheet'!F30,"") -> 0.62589297 | F14: =IFERROR('Profit and Loss'!G4/'Balance Sheet'!G30,"") -> 0.68003193
A15: Inventory T/O Ratio | B15: =IFERROR((ABS('Profit and Loss'!C6)/('Balance Sheet'!C10+'Balance Sheet'!D10)),"") -> 1.9347273 | C15: =IFERROR((ABS('Profit and Loss'!D6)/('Balance Sheet'!D10+'Balance Sheet'!E10)),"") -> 1.8698867 | D15: =IFERROR((ABS('Profit and Loss'!E6)/('Balance Sheet'!E10+'Balance Sheet'!F10)),"") -> 1.9164105 | E15: =IFERROR((ABS('Profit and Loss'!F6)/('Balance Sheet'!F10+'Balance Sheet'!G10)),"") -> 2.0589594 | F15: =IFERROR((ABS('Profit and Loss'!G6)/('Balance Sheet'!G10+'Balance Sheet'!H10)),"") -> 2.2099877
A18: Profitibility Ratios
A19: GP Ratio | B19: =IFERROR('Profit and Loss'!C12/'Profit and Loss'!C4,"") -> 0.16017908 | C19: =IFERROR('Profit and Loss'!D12/'Profit and Loss'!D4,"") -> 0.15613239 | D19: =IFERROR('Profit and Loss'!E12/'Profit and Loss'!E4,"") -> 0.13974201 | E19: =IFERROR('Profit and Loss'!F12/'Profit and Loss'!F4,"") -> 0.1396174 | F19: =IFERROR('Profit and Loss'!G12/'Profit and Loss'!G4,"") -> 0.16875141
A20: NP Ratio | B20: =IFERROR('Profit and Loss'!C24/'Profit and Loss'!C4,"") -> 0.11914092 | C20: =IFERROR('Profit and Loss'!D24/'Profit and Loss'!D4,"") -> 0.12052947 | D20: =IFERROR('Profit and Loss'!E24/'Profit and Loss'!E4,"") -> 0.098174193 | E20: =IFERROR('Profit and Loss'!F24/'Profit and Loss'!F4,"") -> 0.194114 | F20: =IFERROR('Profit and Loss'!G24/'Profit and Loss'!G4,"") -> 0.14502685
A21: Return on Equity | B21: =IFERROR('Profit and Loss'!C24/'Balance Sheet'!C61,"") -> 0.30303199 | C21: =IFERROR('Profit and Loss'!D24/'Balance Sheet'!D61,"") -> 0.31360864 | D21: =IFERROR('Profit and Loss'!E24/'Balance Sheet'!E61,"") -> 0.22080892 | E21: =IFERROR('Profit and Loss'!F24/'Balance Sheet'!F61,"") -> 0.31812194 | F21: =IFERROR('Profit and Loss'!G24/'Balance Sheet'!G61,"") -> 0.26768793
A22: Return on Capital Employed | B22: =IFERROR('Profit and Loss'!C15/('Balance Sheet'!C30-'Balance Sheet'!C42),"") -> 0.152737 | C22: =IFERROR('Profit and Loss'!D15/('Balance Sheet'!D30-'Balance Sheet'!D42),"") -> 0.15718821 | D22: =IFERROR('Profit and Loss'!E15/('Balance Sheet'!E30-'Balance Sheet'!E42),"") -> 0.12946663 | E22: =IFERROR('Profit and Loss'!F15/('Balance Sheet'!F30-'Balance Sheet'!F42),"") -> 0.1178245 | F22: =IFERROR('Profit and Loss'!G15/('Balance Sheet'!G30-'Balance Sheet'!G42),"") -> 0.17550352
A23: Return on Assets | B23: =IFERROR(('Profit and Loss'!C24/'Balance Sheet'!C30),"") -> 0.078153722 | C23: =IFERROR(('Profit and Loss'!D24/'Balance Sheet'!D30),"") -> 0.088573686 | D23: =IFERROR(('Profit and Loss'!E24/'Balance Sheet'!E30),"") -> 0.068574218 | E23: =IFERROR(('Profit and Loss'!F24/'Balance Sheet'!F30),"") -> 0.12149459 | F23: =IFERROR(('Profit and Loss'!G24/'Balance Sheet'!G30),"") -> 0.098622892
A26: Valuation Ratios
A27: EPS | B27: ='Profit and Loss'!C27 -> 4.192604 | C27: ='Profit and Loss'!D27 -> 4.2362056 | D27: ='Profit and Loss'!E27 -> 3.4244551 | E27: ='Profit and Loss'!F27 -> 6.0634864 | F27: ='Profit and Loss'!G27 -> 4.2994728
A28: DPS | B28: ='Profit and Loss'!C28 -> 3.05 | C28: ='Profit and Loss'!D28 -> 3 | D28: ='Profit and Loss'!E28 -> 2.95 | E28: ='Profit and Loss'!F28 -> 2.8 | F28: ='Profit and Loss'!G28 -> 2.75 | H28: https://www.nestle.com/investors/shares-adrs/dividends
A29: Dividend Yield | B29: =B28/B27 -> 0.72747152 | C29: =C28/C27 -> 0.70818093 | D29: =D28/D27 -> 0.86145092 | E29: =E28/E27 -> 0.46178054 | F29: =F28/F27 -> 0.63961331
A30: Market Price | B30: 74.88 | C30: 97.51 | D30: 107.41 | E30: 127.44 | F30: 104.26
A31: P/E Ratio | B31: =B30/B27 -> 17.860022 | C31: =C30/C27 -> 23.018241 | D31: =D30/D27 -> 31.365574 | E31: =E30/E27 -> 21.017611 | F31: =F30/F27 -> 24.249485
A32: Market Value/ Book Value | B32: =B30/(('Balance Sheet'!C30-'Balance Sheet'!C53)/'Balance Sheet'!C70) -> 5.3466765 | C32: =C30/(('Balance Sheet'!D30-'Balance Sheet'!D53)/'Balance Sheet'!D70) -> 7.1550746 | D32: =D30/(('Balance Sheet'!E30-'Balance Sheet'!E53)/'Balance Sheet'!E70) -> 6.9026337 | E32: =E30/(('Balance Sheet'!F30-'Balance Sheet'!F53)/'Balance Sheet'!F70) -> 6.6771567 | F32: =F30/(('Balance Sheet'!G30-'Balance Sheet'!G53)/'Balance Sheet'!G70) -> 6.4576914
