Workbook

Sheet Cover Page
A2: Name: Sambit Kumar Samanta | D2: Pershing Square Holdings Ltd (PSHP.L)
A3: Student Id: ss4083 | D3: Valuation Report
A4: HW id: H00508467
A5: Corporate Finance Coursework 1
A6: Professor: Stefano Maiani

Sheet Sheet3
A1: id | B1: Company name | C1: Date | D1: Month | E1: yyyy/mm | F1: Market Capitalisation | G1: Returns | H1: Size Group | I1: Year | J1: id | K1: BVE | L1: B/M Ratio | M1: BM Group
A2: 95 | B2: PERSHING SQUARE HOLDINGS LTD | C2: 45901 | D2: September 2025 | E2: =TEXT(C2,"yyyy/mm") -> 2025/09 | F2: 11021500 | G2: 0.063691215 | I2: 2025 | J2: PERSHING SQUARE HOLDINGS LTD-2025
A3: 95 | B3: PERSHING SQUARE HOLDINGS LTD | C3: 45870 | D3: August 2025 | E3: =TEXT(C3,"yyyy/mm") -> 2025/08 | F3: 10341415 | G3: 0.01295894 | I3: 2025 | J3: PERSHING SQUARE HOLDINGS LTD-2025
A4: 95 | B4: PERSHING SQUARE HOLDINGS LTD | C4: 45839 | D4: July 2025 | E4: =TEXT(C4,"yyyy/mm") -> 2025/07 | F4: 10208266 | G4: 0.082198664 | I4: 2025 | J4: PERSHING SQUARE HOLDINGS LTD-2025
A5: 95 | B5: PERSHING SQUARE HOLDINGS LTD | C5: 45809 | D5: June 2025 | E5: =TEXT(C5,"yyyy/mm") -> 2025/06 | F5: 9402721.1 | G5: -0.0067341423 | I5: 2025 | J5: PERSHING SQUARE HOLDINGS LTD-2025
A6: 95 | B6: PERSHING SQUARE HOLDINGS LTD | C6: 45778 | D6: May 2025 | E6: =TEXT(C6,"yyyy/mm") -> 2025/05 | F6: 9466254 | G6: 0.094799351 | I6: 2025 | J6: PERSHING SQUARE HOLDINGS LTD-2025
A7: 95 | B7: PERSHING SQUARE HOLDINGS LTD | C7: 45748 | D7: April 2025 | E7: =TEXT(C7,"yyyy/mm") -> 2025/04 | F7: 8610082.6 | G7: -0.049639349 | I7: 2025 | J7: PERSHING SQUARE HOLDINGS LTD-2025
A8: 95 | B8: PERSHING SQUARE HOLDINGS LTD | C8: 45717 | D8: March 2025 | E8: =TEXT(C8,"yyyy/mm") -> 2025/03 | F8: 9048267.1 | G8: -0.13632631 | I8: 2025 | J8: PERSHING SQUARE HOLDINGS LTD-2025
A9: 95 | B9: PERSHING SQUARE HOLDINGS LTD | C9: 45689 | D9: February 2025 | E9: =TEXT(C9,"yyyy/mm") -> 2025/02 | F9: 10369819 | G9: -0.15719805 | I9: 2025 | J9: PERSHING SQUARE HOLDINGS LTD-2025
A10: 95 | B10: PERSHING SQUARE HOLDINGS LTD | C10: 45658 | D10: January 2025 | E10: =TEXT(C10,"yyyy/mm") -> 2025/01 | F10: 12135046 | G10: 0.16442912 | I10: 2025 | J10: PERSHING SQUARE HOLDINGS LTD-2025
A11: 95 | B11: PERSHING SQUARE HOLDINGS LTD | C11: 45627 | D11: December 2024 | E11: =TEXT(C11,"yyyy/mm") -> 2024/12 | F11: 10295105 | G11: 0.033458494 | I11: 2024 | J11: PERSHING SQUARE HOLDINGS LTD-2024
A12: 95 | B12: PERSHING SQUARE HOLDINGS LTD | C12: 45597 | D12: November 2024 | E12: =TEXT(C12,"yyyy/mm") -> 2024/11 | F12: 9956344.7 | G12: 0.080796087 | I12: 2024 | J12: PERSHING SQUARE HOLDINGS LTD-2024
A13: 95 | B13: PERSHING SQUARE HOLDINGS LTD | C13: 45566 | D13: October 2024 | E13: =TEXT(C13,"yyyy/mm") -> 2024/10 | F13: 9183550.8 | G13: -0.018275762 | I13: 2024 | J13: PERSHING SQUARE HOLDINGS LTD-2024
... A22: 95 | B22: PERSHING SQUARE HOLDINGS LTD | C22: 45292 | D22: January 2024 | E22: =TEXT(C22,"yyyy/mm") -> 2024/01 | F22: 10003983 | G22: 0.038212918 | I22: 2024 | J22: PERSHING SQUARE HOLDINGS LTD-2024
A23: 95 | B23: PERSHING SQUARE HOLDINGS LTD | C23: 45261 | D23: December 2023 | E23: 2023/12 | F23: 9628913.3 | G23: 0.13928772 | H23: Small | I23: 2023 | J23: PERSHING SQUARE HOLDINGS LTD-2023 | K23: 12058441 | L23: 1.2523158 | M23: High
A24: 95 | B24: PERSHING SQUARE HOLDINGS LTD | C24: 45231 | D24: November 2023 | E24: 2023/11 | F24: 8376939.7 | G24: 0.062189383 | H24: Small | I24: 2023 | J24: PERSHING SQUARE HOLDINGS LTD-2023 | K24: 12058441 | L24: 1.4394804 | M24: High
A25: 95 | B25: PERSHING SQUARE HOLDINGS LTD | C25: 45200 | D25: October 2023 | E25: 2023/10 | F25: 7871851.3 | G25: -0.01826229 | H25: Small | I25: 2023 | J25: PERSHING SQUARE HOLDINGS LTD-2023 | K25: 12058441 | L25: 1.531843 | M25: High
A26: 95 | B26: PERSHING SQUARE HOLDINGS LTD | C26: 45170 | D26: September 2023 | E26: 2023/09 | F26: 8016930.1 | G26: -0.0013395517 | H26: Small | I26: 2023 | J26: PERSHING SQUARE HOLDINGS LTD-2023 | K26: 12058441 | L26: 1.504122 | M26: High
A27: 95 | B27: PERSHING SQUARE HOLDINGS LTD | C27: 45139 | D27: August 2023 | E27: 2023/08 | F27: 8027676.4 | G27: -0.0033411452 | H27: Small | I27: 2023 | J27: PERSHING SQUARE HOLDINGS LTD-2023 | K27: 12058441 | L27: 1.5021085 | M27: High
A28: 95 | B28: PERSHING SQUARE HOLDINGS LTD | C28: 45108 | D28: July 2023 | E28: 2023/07 | F28: 8054542.9 | G28: 0.05062639 | H28: Small | I28: 2023 | J28: PERSHING SQUARE HOLDINGS LTD-2023 | K28: 12058441 | L28: 1.4970981 | M28: High
A29: 95 | B29: PERSHING SQUARE HOLDINGS LTD | C29: 45078 | D29: June 2023 | E29: 2023/06 | F29: 7656920.5 | G29: 0.036445637 | H29: Small | I29: 2023 | J29: PERSHING SQUARE HOLDINGS LTD-2023 | K29: 12058441 | L29: 1.5748421 | M29: High
A30: 95 | B30: PERSHING SQUARE HOLDINGS LTD | C30: 45047 | D30: May 2023 | E30: 2023/05 | F30: 7382883.2 | G30: -0.0043573358 | H30: Small | I30: 2023 | J30: PERSHING SQUARE HOLDINGS LTD-2023 | K30: 12058441 | L30: 1.633297 | M30: High
A31: 95 | B31: PERSHING SQUARE HOLDINGS LTD | C31: 45017 | D31: April 2023 | E31: 2023/04 | F31: 7415123.1 | G31: -0.030837531 | H31: Small | I31: 2023 | J31: PERSHING SQUARE HOLDINGS LTD-2023 | K31: 12058441 | L31: 1.6261956 | M31: High
A32: 95 | B32: PERSHING SQUARE HOLDINGS LTD | C32: 44986 | D32: March 2023 | E32: 2023/03 | F32: 7647349.4 | G32: -0.039901204 | H32: Small | I32: 2023 | J32: PERSHING SQUARE HOLDINGS LTD-2023 | K32: 12058441 | L32: 1.5768131 | M32: High
A33: 95 | B33: PERSHING SQUARE HOLDINGS LTD | C33: 44958 | D33: February 2023 | E33: 2023/02 | F33: 7958657.3 | G33: 0.013698831 | H33: Small | I33: 2023 | J33: PERSHING SQUARE HOLDINGS LTD-2023 | K33: 12058441 | L33: 1.5151351 | M33: High
A34: 95 | B34: PERSHING SQUARE HOLDINGS LTD | C34: 44927 | D34: January 2023 | E34: 2023/01 | F34: 7850376.4 | G34: 0.04867694 | H34: Small | I34: 2023 | J34: PERSHING SQUARE HOLDINGS LTD-2023 | K34: 12058441 | L34: 1.5360335 | M34: High
... A65: 95 | B65: PERSHING SQUARE HOLDINGS LTD | C65: 42887 | D65: June 2017 | E65: 2017/06 | F65: 3750639.9 | G65: -0.044000287 | H65: Small | I65: 2017 | J65: PERSHING SQUARE HOLDINGS LTD-2017 | K65: 4083525.3 | L65: 1.0887543 | M65: High

Sheet Rf
A1: Month | B1: Short | C1: Medium | D1: Long | E1: Ultra-Long | F1: month | G1: Rf
A2: 45870 | B2: 4.0479128 | C2: 4.6356792 | D2: 5.4823878 | E2: 4.8708482 | F2: =TEXT(A2,"yyyy/mm") -> 2025/08 | G2: =(1+C2)^(1/12)-1 -> 0.15499168
A3: 45839 | B3: 4.0280961 | C3: 4.6016629 | D3: 5.416919 | E3: 4.7772733 | F3: =TEXT(A3,"yyyy/mm") -> 2025/07 | G3: =(1+C3)^(1/12)-1 -> 0.15440912
A4: 45809 | B4: 4.044523 | C4: 4.5448828 | D4: 5.2752718 | E4: 4.587292 | F4: =TEXT(A4,"yyyy/mm") -> 2025/06 | G4: =(1+C4)^(1/12)-1 -> 0.15342944
A5: 45778 | B5: 4.1019664 | C5: 4.6284487 | D5: 5.3952485 | E5: 4.6349634 | F5: =TEXT(A5,"yyyy/mm") -> 2025/05 | G5: =(1+C5)^(1/12)-1 -> 0.15486812
A6: 45748 | B6: 4.0787748 | C6: 4.58018 | D6: 5.3131879 | E6: 4.4742039 | F6: =TEXT(A6,"yyyy/mm") -> 2025/04 | G6: =(1+C6)^(1/12)-1 -> 0.15403953
A7: 45717 | B7: 4.3124567 | C7: 4.6778686 | D7: 5.2623348 | E7: 4.4904287 | F7: =TEXT(A7,"yyyy/mm") -> 2025/03 | G7: =(1+C7)^(1/12)-1 -> 0.15570975
A8: 45689 | B8: 4.1996639 | C8: 4.5134771 | D8: 5.1055883 | E8: 4.3696506 | F8: =TEXT(A8,"yyyy/mm") -> 2025/02 | G8: =(1+C8)^(1/12)-1 -> 0.15288361
A9: 45658 | B9: 4.3914605 | C9: 4.6660063 | D9: 5.2271423 | E9: 4.5360834 | F9: =TEXT(A9,"yyyy/mm") -> 2025/01 | G9: =(1+C9)^(1/12)-1 -> 0.15550835
A10: 45627 | B10: 4.2434284 | C10: 4.4238876 | D10: 4.9660902 | E10: 4.3877881 | F10: =TEXT(A10,"yyyy/mm") -> 2024/12 | G10: =(1+C10)^(1/12)-1 -> 0.15131074
A11: 45597 | B11: 4.3028069 | C11: 4.4300156 | D11: 4.8862944 | E11: 4.3488882 | F11: =TEXT(A11,"yyyy/mm") -> 2024/11 | G11: =(1+C11)^(1/12)-1 -> 0.15141908
A12: 45566 | B12: 4.0403174 | C12: 4.177002 | D12: 4.7034131 | E12: 4.202914 | F12: =TEXT(A12,"yyyy/mm") -> 2024/10 | G12: =(1+C12)^(1/12)-1 -> 0.14684976
A13: 45536 | B13: 3.7555582 | C13: 3.8956905 | D13: 4.4649481 | E13: 4.0098882 | F13: =TEXT(A13,"yyyy/mm") -> 2024/09 | G13: =(1+C13)^(1/12)-1 -> 0.14152255
... A129: 42005 | B129: 1.1557218 | C129: 1.5376951 | D129: 2.2482646 | E129: 2.2058728 | F129: =TEXT(A129,"yyyy/mm") -> 2015/01 | G129: =(1+C129)^(1/12)-1 -> 0.080695361
A132: Note: | B132: 1. The historical monthly average gilt yields quoted on this page are simple averages of the close of business redemption yields for each month of the prevailing 5 (short), 10 (medium) and 30 year (long) benchmark gilts. From June 2005, ultra-long yields are reported - these are the simple averages of the close of business yields of the 50-year benchmark gilt. The DMO regards all gilts with a maturity of over 15 years as long - the distinction between long and ultra-long in this report is simply to distinguish between 30- and 50-year yields. Before April 1999, the long yields reported are simple averages of the close of business yields on the prevailing 20-year benchmark gilt._x000D_2. Since 24 July 2017 the daily yields used in these calculations have been derived by the DMO from the Tradeweb FTSE Gilt Closing Prices. Prior to that, the yields were derived from the GEMMA reference prices._x000D_3. The formulae used by the DMO to calculate these redemption yields appear in the paper "Formulae for Calculating Gilt Prices from Yields", an electronic copy of which is available on this website._x000D_4. Although the DMO does not publish historical rates from its yield curve model, rates from the Bank of England's model are available. These can be accessed at: www.bankofengland.co.uk/statistics/yield-curves.
A134: Page -1 of 1

Sheet Market Cap
A1: id | B1: Company name | C1: Month | D1: Market Capitalisation | E1: date | F1: Returns
A2: 54 | B2: 3I GROUP PLC | C2: September 2025 | D2: 54564802 | E2: 45901 | F2: =IF(B2=B3,LN(D2/D3),NA()) -> 0.037522358
A3: 54 | B3: 3I GROUP PLC | C3: August 2025 | D3: 52555337 | E3: 45870 | F3: =IF(B3=B4,LN(D3/D4),NA()) -> -0.03231499
A4: 54 | B4: 3I GROUP PLC | C4: July 2025 | D4: 54281401 | E4: 45839 | F4: =IF(B4=B5,LN(D4/D5),NA()) -> 0.0075052258
A5: 54 | B5: 3I GROUP PLC | C5: June 2025 | D5: 53875532 | E5: 45809 | F5: =IF(B5=B6,LN(D5/D6),NA()) -> 0.011720928
A6: 54 | B6: 3I GROUP PLC | C6: May 2025 | D6: 53247747 | E6: 45778 | F6: =IF(B6=B7,LN(D6/D7),NA()) -> -0.039011323
A7: 54 | B7: 3I GROUP PLC | C7: April 2025 | D7: 55366063 | E7: 45748 | F7: =IF(B7=B8,LN(D7/D8),NA()) -> 0.15778003
A8: 54 | B8: 3I GROUP PLC | C8: March 2025 | D8: 47284700 | E8: 45717 | F8: =IF(B8=B9,LN(D8/D9),NA()) -> -0.090116086
A9: 54 | B9: 3I GROUP PLC | C9: February 2025 | D9: 51743710 | E9: 45689 | F9: =IF(B9=B10,LN(D9/D10),NA()) -> 0.013485415
A10: 54 | B10: 3I GROUP PLC | C10: January 2025 | D10: 51050608 | E10: 45658 | F10: =IF(B10=B11,LN(D10/D11),NA()) -> 0.15954379
A11: 54 | B11: 3I GROUP PLC | C11: December 2024 | D11: 43522310 | E11: 45627 | F11: =IF(B11=B12,LN(D11/D12),NA()) -> -0.03987881
A12: 54 | B12: 3I GROUP PLC | C12: November 2024 | D12: 45292999 | E12: 45597 | F12: =IF(B12=B13,LN(D12/D13),NA()) -> 0.15640054
A13: 54 | B13: 3I GROUP PLC | C13: October 2024 | D13: 38735324 | E13: 45566 | F13: =IF(B13=B14,LN(D13/D14),NA()) -> -0.041072729
... A12068: 29 | B12068: WPP PLC | C12068: January 2015 | D12068: 28569912 | E12068: 42005 | F12068: =IF(B12068=B12069,LN(D12068/D12069),NA()) -> #N/A

Sheet FTSE
A1: id | B1: Company name | C1: Date | D1: Month | E1: yyyy/mm | F1: Market Capitalisation | G1: Returns | H1: Size Group | I1: Year | J1: id | K1: BVE | L1: B/M Ratio | M1: BM Group
A2: 54 | B2: 3I GROUP PLC | C2: 45901 | D2: September 2025 | E2: =TEXT(C2,"yyyy/mm") -> 2025/09 | F2: 54564802 | G2: 0.037522358 | H2: Big | I2: 2025 | J2: 3I GROUP PLC-2025 | K2: 31845963 | L2: 0.58363565 | M2: Mid
A3: 54 | B3: 3I GROUP PLC | C3: 45870 | D3: August 2025 | E3: =TEXT(C3,"yyyy/mm") -> 2025/08 | F3: 52555337 | G3: -0.03231499 | H3: Big | I3: 2025 | J3: 3I GROUP PLC-2025 | K3: 31845963 | L3: 0.60595108 | M3: Mid
A4: 54 | B4: 3I GROUP PLC | C4: 45839 | D4: July 2025 | E4: =TEXT(C4,"yyyy/mm") -> 2025/07 | F4: 54281401 | G4: 0.0075052258 | H4: Big | I4: 2025 | J4: 3I GROUP PLC-2025 | K4: 31845963 | L4: 0.58668278 | M4: Mid
A5: 54 | B5: 3I GROUP PLC | C5: 45809 | D5: June 2025 | E5: =TEXT(C5,"yyyy/mm") -> 2025/06 | F5: 53875532 | G5: 0.011720928 | H5: Big | I5: 2025 | J5: 3I GROUP PLC-2025 | K5: 31845963 | L5: 0.59110253 | M5: Mid
A6: 54 | B6: 3I GROUP PLC | C6: 45778 | D6: May 2025 | E6: =TEXT(C6,"yyyy/mm") -> 2025/05 | F6: 53247747 | G6: -0.039011323 | H6: Big | I6: 2025 | J6: 3I GROUP PLC-2025 | K6: 31845963 | L6: 0.59807156 | M6: Mid
A7: 54 | B7: 3I GROUP PLC | C7: 45748 | D7: April 2025 | E7: =TEXT(C7,"yyyy/mm") -> 2025/04 | F7: 55366063 | G7: 0.15778003 | H7: Big | I7: 2025 | J7: 3I GROUP PLC-2025 | K7: 31845963 | L7: 0.57518924 | M7: Mid
A8: 54 | B8: 3I GROUP PLC | C8: 45717 | D8: March 2025 | E8: =TEXT(C8,"yyyy/mm") -> 2025/03 | F8: 47284700 | G8: -0.090116086 | H8: Big | I8: 2025 | J8: 3I GROUP PLC-2025 | K8: 31845963 | L8: 0.67349403 | M8: Mid
A9: 54 | B9: 3I GROUP PLC | C9: 45689 | D9: February 2025 | E9: =TEXT(C9,"yyyy/mm") -> 2025/02 | F9: 51743710 | G9: 0.013485415 | H9: Big | I9: 2025 | J9: 3I GROUP PLC-2025 | K9: 31845963 | L9: 0.61545574 | M9: Mid
A10: 54 | B10: 3I GROUP PLC | C10: 45658 | D10: January 2025 | E10: =TEXT(C10,"yyyy/mm") -> 2025/01 | F10: 51050608 | G10: 0.15954379 | H10: Big | I10: 2025 | J10: 3I GROUP PLC-2025 | K10: 31845963 | L10: 0.62381163 | M10: Mid
A11: 54 | B11: 3I GROUP PLC | C11: 45627 | D11: December 2024 | E11: =TEXT(C11,"yyyy/mm") -> 2024/12 | F11: 43522310 | G11: -0.03987881 | H11: Big | I11: 2024 | J11: 3I GROUP PLC-2024 | K11: 25439546 | L11: 0.58451736 | M11: Mid
A12: 54 | B12: 3I GROUP PLC | C12: 45597 | D12: November 2024 | E12: =TEXT(C12,"yyyy/mm") -> 2024/11 | F12: 45292999 | G12: 0.15640054 | H12: Big | I12: 2024 | J12: 3I GROUP PLC-2024 | K12: 25439546 | L12: 0.56166617 | M12: Mid
A13: 54 | B13: 3I GROUP PLC | C13: 45566 | D13: October 2024 | E13: =TEXT(C13,"yyyy/mm") -> 2024/10 | F13: 38735324 | G13: -0.041072729 | H13: Big | I13: 2024 | J13: 3I GROUP PLC-2024 | K13: 25439546 | L13: 0.65675314 | M13: Mid
... A11243: 29 | B11243: WPP PLC | C11243: 42036 | D11243: February 2015 | E11243: =TEXT(C11243,"yyyy/mm") -> 2015/02 | F11243: 29868351 | G11243: 0.044445315 | H11243: Big | I11243: 2015 | J11243: WPP PLC-2015 | K11243: 11318322 | L11243: 0.37894031 | M11243: Mid

Sheet SMB and HML
C1: SMB | I1: HML
C3: date | D3: Big | E3: Small | F3: SMB | I3: date | J3: High | K3: Low | L3: Mid | M3: HML
A4: =TEXT(C4,"yyyy/mm") -> 2015/02 | C4: 42036 | D4: 0.029084946 | E4: 0.046099837 | F4: =E4-D4 -> 0.01701489 | I4: 42036 | J4: 0.053352284 | K4: 0.030954226 | L4: 0.030616953 | M4: =J4-K4 -> 0.022398058
A5: =TEXT(C5,"yyyy/mm") -> 2015/03 | C5: 42064 | D5: -0.014825856 | E5: -0.013904378 | F5: =E5-D5 -> 0.00092147836 | I5: 42064 | J5: -0.013248135 | K5: -0.018270425 | L5: -0.012232868 | M5: =J5-K5 -> 0.00502229
A6: =TEXT(C6,"yyyy/mm") -> 2015/04 | C6: 42095 | D6: 0.020738316 | E6: 0.024236013 | F6: =E6-D6 -> 0.0034976971 | I6: 42095 | J6: 0.036611538 | K6: 0.018833314 | L6: 0.014759028 | M6: =J6-K6 -> 0.017778224
A7: =TEXT(C7,"yyyy/mm") -> 2015/05 | C7: 42125 | D7: 0.010163466 | E7: 0.05075919 | F7: =E7-D7 -> 0.040595724 | I7: 42125 | J7: 0.021161547 | K7: 0.027016973 | L7: 0.040508338 | M7: =J7-K7 -> -0.0058554253
A8: =TEXT(C8,"yyyy/mm") -> 2015/06 | C8: 42156 | D8: -0.063680418 | E8: -0.037154777 | F8: =E8-D8 -> 0.026525641 | I8: 42156 | J8: -0.056363688 | K8: -0.046383301 | L8: -0.04861847 | M8: =J8-K8 -> -0.0099803873
A9: =TEXT(C9,"yyyy/mm") -> 2015/07 | C9: 42186 | D9: 0.0211083 | E9: 0.019626754 | F9: =E9-D9 -> -0.0014815456 | I9: 42186 | J9: -0.0021837087 | K9: 0.044304268 | L9: 0.01931713 | M9: =J9-K9 -> -0.046487977
A10: =TEXT(C10,"yyyy/mm") -> 2015/08 | C10: 42217 | D10: -0.062047563 | E10: -0.026552575 | F10: =E10-D10 -> 0.035494988 | I10: 42217 | J10: -0.070734776 | K10: -0.029598602 | L10: -0.035076877 | M10: =J10-K10 -> -0.041136174
A11: =TEXT(C11,"yyyy/mm") -> 2015/09 | C11: 42248 | D11: -0.034228603 | E11: -0.033158932 | F11: =E11-D11 -> 0.001069671 | I11: 42248 | J11: -0.071269231 | K11: -0.0067393246 | L11: -0.025788586 | M11: =J11-K11 -> -0.064529907
A12: =TEXT(C12,"yyyy/mm") -> 2015/10 | C12: 42278 | D12: 0.045391658 | E12: 0.042865444 | F12: =E12-D12 -> -0.0025262148 | I12: 42278 | J12: 0.056716868 | K12: 0.05542988 | L12: 0.026345869 | M12: =J12-K12 -> 0.0012869881
A13: =TEXT(C13,"yyyy/mm") -> 2015/11 | C13: 42309 | D13: -0.011030675 | E13: 0.024861858 | F13: =E13-D13 -> 0.035892532 | I13: 42309 | J13: -0.025376978 | K13: 0.037409435 | L13: 0.0083439917 | M13: =J13-K13 -> -0.062786412
A14: =TEXT(C14,"yyyy/mm") -> 2015/12 | C14: 42339 | D14: -0.0059578555 | E14: -0.0075059775 | F14: =E14-D14 -> -0.001548122 | I14: 42339 | J14: -0.030787217 | K14: 0.0066260762 | L14: 0.0017630043 | M14: =J14-K14 -> -0.037413293
A15: =TEXT(C15,"yyyy/mm") -> 2016/01 | C15: 42370 | D15: -0.21021176 | E15: -0.28967652 | F15: =E15-D15 -> -0.079464762 | I15: 42370 | J15: -0.32985984 | K15: -0.19791313 | L15: -0.22780042 | M15: =J15-K15 -> -0.13194672
... A131: =TEXT(C131,"yyyy/mm") -> 2025/09 | C131: 45901 | D131: 0.023393962 | E131: 0.023136533 | F131: =E131-D131 -> -0.00025742969 | I131: 45901 | J131: 0.055786634 | K131: 0.02275012 | L131: -0.0032958742 | M131: =J131-K131 -> 0.033036514

Sheet CAPM Reg
A1: SUMMARY OUTPUT
A3: Regression Statistics
A4: Multiple R | B4: 0.44132521
A5: R Square | B5: 0.19476794
A6: Adjusted R Square | B6: 0.18646658
A7: Standard Error | B7: 0.059870665
A8: Observations | B8: 99
A10: ANOVA
B11: df | C11: SS | D11: MS | E11: F | F11: Significance F
A12: Regression | B12: 1 | C12: 0.084100061 | D12: 0.084100061 | E12: 23.462169 | F12: 4.8224904e-06
A13: Residual | B13: 97 | C13: 0.34769616 | D13: 0.0035844965
A14: Total | B14: 98 | C14: 0.43179622
B16: Coefficients | C16: Standard Error | D16: t Stat | E16: P-value | F16: Lower 95% | G16: Upper 95% | H16: Lower 95.0% | I16: Upper 95.0%
A17: alpha | B17: 0.01082747 | C17: 0.0060174025 | D17: 1.7993595 | E17: 0.075071181 | F17: -0.0011154081 | G17: 0.022770348 | H17: -0.0011154081 | I17: 0.022770348
A18: ß(Rm-Rf) | B18: 0.81308247 | C18: 0.16786128 | D18: 4.8437763 | E18: 4.8224904e-06 | F18: 0.4799243 | G18: 1.1462406 | H18: 0.4799243 | I18: 1.1462406

Sheet FF3 Reg
A1: SUMMARY OUTPUT
A3: Regression Statistics
A4: Multiple R | B4: 0.53930309
A5: R Square | B5: 0.29084782
A6: Adjusted R Square | B6: 0.26845354
A7: Standard Error | B7: 0.056773718
A8: Observations | B8: 99
A10: ANOVA
B11: df | C11: SS | D11: MS | E11: F | F11: Significance F
A12: Regression | B12: 3 | C12: 0.12558699 | D12: 0.04186233 | E12: 12.987595 | F12: 3.52127e-07
A13: Residual | B13: 95 | C13: 0.30620923 | D13: 0.003223255
A14: Total | B14: 98 | C14: 0.43179622
B16: Coefficients | C16: Standard Error | D16: t Stat | E16: P-value | F16: Lower 95% | G16: Upper 95% | H16: Lower 95.0% | I16: Upper 95.0%
A17: alpha | B17: 0.00293713 | C17: 0.0061630387 | D17: 0.47657173 | E17: 0.63476146 | F17: -0.0092980487 | G17: 0.015172309 | H17: -0.0092980487 | I17: 0.015172309
A18: ß(Rm-Rf) | B18: 1.0862394 | C18: 0.17740245 | D18: 6.1230239 | E18: 2.0573953e-08 | F18: 0.73405103 | G18: 1.4384278 | H18: 0.73405103 | I18: 1.4384278
A19: ßsmb | B19: -0.15153018 | C19: 0.23860428 | D19: -0.63506898 | E19: 0.52691007 | F19: -0.62521956 | G19: 0.32215921 | H19: -0.62521956 | I19: 0.32215921
A20: ßhml | B20: -0.6705656 | C20: 0.19086439 | D20: -3.5133092 | E20: 0.00067950426 | F20: -1.0494793 | G20: -0.29165188 | H20: -1.0494793 | I20: -0.29165188

Sheet Prices and Returns
A18: Month | B18: PSH price close | C18: PSH return | D18: Excess PSH | E18: Market Return | F18: Rf | G18: Excess Market | H18: SMB | I18: HML
A19: 2025/08 | B19: 57.95374 | C19: 0.016359328 | D19: =C19-F19 -> 0.012575988 | E19: 0.0059530256 | F19: 0.0037833396 | G19: 0.002169686 | H19: -0.022541058 | I19: -0.020475449 | M19: Average | N19: Medians
A20: 2025/07 | B20: 57.013369 | C20: 0.087096988 | D20: =C20-F20 -> 0.083340846 | E20: 0.041567936 | F20: 0.003756142 | G20: 0.037811794 | H20: -0.051905908 | I20: 0.0050267131 | L20: Rf | M20: =AVERAGE(F19:F117) -> 0.0017500481 | N20: =MEDIAN(F19:F117) -> 0.0011743328
A21: 2025/06 | B21: 52.25778 | C21: -0.0061506344 | D21: =C21-F21 -> -0.00986136 | E21: -0.0013026613 | F21: 0.0037107256 | G21: -0.0050133869 | H21: 0.0064164098 | I21: -0.017395041 | L21: MRP | M21: =AVERAGE(G19:G117) -> 0.00027285048 | N21: =MEDIAN(G19:G117) -> 0.0070129663
A22: 2025/05 | B22: 52.580189 | C22: 0.094799355 | D22: =C22-F22 -> 0.091021796 | E22: 0.032148052 | F22: 0.0037775591 | G22: 0.028370493 | H22: 0.012787113 | I22: 0.019316126 | L22: SMB | M22: =AVERAGE(H19:H117) -> -0.0049719142 | N22: =MEDIAN(H19:H117) -> -0.0047746598
A23: 2025/04 | B23: 47.824596 | C23: -0.048255058 | D23: =C23-F23 -> -0.05199402 | E23: -0.010301268 | F23: 0.0037389612 | G23: -0.014040229 | H23: 0.026146431 | I23: -0.028928049 | L23: HML | M23: =AVERAGE(I19:I117) -> -0.010532026 | N23: =MEDIAN(I19:I117) -> -0.006601361
A24: 2025/03 | B24: 50.188962 | C24: -0.13031423 | D24: =C24-F24 -> -0.13413129 | E24: -0.026096562 | F24: 0.0038170607 | G24: -0.029913623 | H24: -0.0065819332 | I24: -0.070925767
A25: 2025/02 | B25: 57.174578 | C25: -0.0060904146 | D25: =C25-F25 -> -0.0097760101 | E25: 0.015532494 | F25: 0.0036855955 | G25: 0.011846898 | H25: -0.031810564 | I25: 0.0024429015 | L25: r(CAPM) | M25: =M20+'CAPM Reg'!B18*'Prices and Returns'!M21 -> 0.0019718981 | N25: =N20+'CAPM Reg'!B18*'Prices and Returns'!N21 -> 0.0068764527
A26: 2025/01 | B26: 57.523857 | C26: 0.16442911 | D26: =C26-F26 -> 0.16062153 | E26: 0.059486948 | F26: 0.0038075807 | G26: 0.055679368 | H26: -0.0087507483 | I26: -0.024370302 | L26: R(FF3) | M26: =M20+'FF3 Reg'!B18*'Prices and Returns'!M21+'FF3 Reg'!B19*'Prices and Returns'!M22+'FF3 Reg'!B20*'Prices and Returns'!M23 -> 0.0098622381 | N26: =N20+N21*'FF3 Reg'!B18+'FF3 Reg'!B19*'Prices and Returns'!N22+'Prices and Returns'!N23*'FF3 Reg'!B20 -> 0.013942244
A27: 2024/12 | B27: 48.801969 | C27: 0.033458505 | D27: =C27-F27 -> 0.029844634 | E27: -0.013885737 | F27: 0.0036138703 | G27: -0.017499607 | H27: 0.0008634185 | I27: 0.0045437703
A28: 2024/11 | B28: 47.196142 | C28: 0.080796082 | D28: =C28-F28 -> 0.077177303 | E28: 0.021614024 | F28: 0.0036187782 | G28: 0.017995246 | H28: -0.023385217 | I28: -0.052834329 | L28: Annualised
A29: 2024/10 | B29: 43.532861 | C29: -0.018275751 | D29: =C29-F29 -> -0.021691673 | E29: -0.015519931 | F29: 0.0034159217 | G29: -0.018935853 | H29: -0.015202316 | I29: 0.017456806 | L29: R(CAPM) | M29: =(1+M25)^12-1 -> 0.023921104 | N29: =(1+N25)^12-1 -> 0.085710936
A30: 2024/09 | B30: 44.335771 | C30: -0.055585173 | D30: =C30-F30 -> -0.05877502 | E30: -0.016815556 | F30: 0.0031898463 | G30: -0.020005402 | H30: 0.010187055 | I30: -0.0025211756 | L30: R(FF3) | M30: =(1+M26)^12-1 -> 0.12498205 | N30: =(1+N26)^12-1 -> 0.18075178
A31: 2024/08 | B31: 46.869962 | C31: -0.030576947 | D31: =C31-F31 -> -0.03380988 | E31: 0.0010331684 | F31: 0.0032329332 | G31: -0.0021997648 | H31: -0.0027956616 | I31: -0.014976683
A32: 2024/07 | B32: 48.325238 | C32: -0.082197107 | D32: =C32-F32 -> -0.085565665 | E32: 0.024663574 | F32: 0.003368558 | G32: 0.021295016 | H32: 0.013568669 | I32: 0.021697756
A33: 2024/06 | B33: 52.46525 | C33: 0.025182953 | D33: =C33-F33 -> 0.02179189 | E33: -0.013535898 | F33: 0.003391063 | G33: -0.016926961 | H33: -0.031406368 | I33: -0.017869728 | K33: In estimating PSH’s cost of equity, I apply CAPM and FF3 side by side.
A34: 2024/05 | B34: 51.160518 | C34: 0.033411236 | D34: =C34-F34 -> 0.029968789 | E34: 0.015987419 | F34: 0.0034424473 | G34: 0.012544972 | H34: 0.013460771 | I34: 0.012960766 | K34: For CAPM, I use the median of data to avoid distortion from extreme data like those during covid, which yields a cost of equity of 8.57% annually.
A35: 2024/04 | B35: 49.479422 | C35: -0.033411236 | D35: =C35-F35 -> -0.036847063 | E35: 0.023795988 | F35: 0.0034358271 | G35: 0.020360161 | H35: -0.015914042 | I35: 0.051138644 | K35: For FF3, I use the mean factor premiums, consistent with the model’s theoretical definition of expected returns, which yields 12.5% annually.
A36: 2024/03 | B36: 51.160518 | C36: 0.034425874 | D36: =C36-F36 -> 0.031144975 | E36: 0.041410968 | F36: 0.0032808988 | G36: 0.038130069 | H36: -0.013749455 | I36: 0.014474707 | K36: This ensures that the cost of equity is consistent with overall long term cost of equity and that neither model is biased by the peculiarities of the sample period due to factors like covid.
A37: 2024/02 | B37: 49.429244 | C37: 0.041456791 | D37: =C37-F37 -> 0.038150416 | E37: -7.2081093e-05 | F37: 0.0033063753 | G37: -0.0033784564 | H37: -0.036990682 | I37: -0.027359159
A38: 2024/01 | B38: 47.421961 | C38: 0.038212916 | D38: =C38-F38 -> 0.035066127 | E38: -0.013365373 | F38: 0.0031467891 | G38: -0.016512162 | H38: -0.019803726 | I38: -0.025970796
A39: 2023/12 | B39: 45.644016 | C39: 0.13928772 | D39: =C39-F39 -> 0.13618587 | E39: 0.03681066 | F39: 0.0031018497 | G39: 0.03370881 | H39: 0.021130694 | I39: 0.0036489509
A40: 2023/11 | B40: 39.709275 | C40: 0.062189382 | D40: =C40-F40 -> 0.058732337 | E40: 0.017871988 | F40: 0.0034570444 | G40: 0.014414944 | H40: 0.026805216 | I40: 0.014426392
A41: 2023/10 | B41: 37.315001 | C41: -0.018262293 | D41: =C41-F41 -> -0.021970289 | E41: -0.038365567 | F41: 0.0037079956 | G41: -0.042073563 | H41: -0.011879046 | I41: -0.018311076
A42: 2023/09 | B42: 38.002719 | C42: -0.0013395515 | D42: =C42-F42 -> -0.004921996 | E42: 0.022456934 | F42: 0.0035824446 | G42: 0.018874489 | H42: -0.031886178 | I42: 0.011601258
A43: 2023/08 | B43: 38.053659 | C43: -0.0033411659 | D43: =C43-F43 -> -0.0070092874 | E43: -0.034389796 | F43: 0.0036681215 | G43: -0.038057918 | H43: -0.0011081742 | I43: -0.016328361
A44: 2023/07 | B44: 38.181016 | C44: 0.050626405 | D44: =C44-F44 -> 0.047028963 | E44: 0.022045494 | F44: 0.0035974422 | G44: 0.018448052 | H44: 0.030998387 | I44: 0.004918886
A45: 2023/06 | B45: 36.296162 | C45: 0.03644562 | D45: =C45-F45 -> 0.032918688 | E45: 0.011402431 | F45: 0.0035269315 | G45: 0.0078754996 | H45: -0.026229929 | I45: -0.03280875
A46: 2023/05 | B46: 34.997142 | C46: -0.0043573054 | D46: =C46-F46 -> -0.0075857046 | E46: -0.055434709 | F46: 0.0032283992 | G46: -0.058663109 | H46: 0.019910823 | I46: -0.021734253
A47: 2023/04 | B47: 35.149968 | C47: -0.023277685 | D47: =C47-F47 -> -0.026257684 | E47: 0.03081462 | F47: 0.0029799988 | G47: 0.027834621 | H47: -0.012415888 | I47: 0.0060162515
A48: 2023/03 | B48: 35.977775 | C48: -0.039901217 | D48: =C48-F48 -> -0.042796052 | E48: -0.031539845 | F48: 0.0028948355 | G48: -0.03443468 | H48: 0.0022973474 | I48: -0.074537898
... A117: 2017/06 | B117: 15.6193 | C117: -0.044000329 | D117: =C117-F117 -> -0.044866408 | E117: -0.027944191 | F117: 0.00086607877 | G117: -0.02881027 | H117: -0.01627808 | I117: 0.015774767

Sheet WACC
A1: Pershing Square Holdings Ltd (PSHP.L)
B8: 2015 | C8: 2016 | D8: 2017 | E8: 2018 | F8: 2019 | G8: 2020 | H8: 2021 | I8: 2022 | J8: 2023 | K8: 2024
A9: Cost of Debt (Co is tax exempt)
A10: tax-exempt Guernsey entity under The Income Tax (Exempt Bodies) (Guernsey) Ordinance 1989. The only tax the Co pays is US withholding tax which is not a tax component
A12: Total Debt (millions USD) | B12: 1585.11 | C12: 1560 | D12: 1171.7 | E12: 1103.46 | F12: 1575.25 | G12: 2122.79 | H12: 3009.42 | I12: 2332.57 | J12: 2351.92 | K12: 2320.8
A13: Interest expense | B13: 45.35 | C13: 64.81 | D13: 64.67 | E13: 60.29 | F13: 66.38 | G13: 83.48 | H13: 105.5 | I13: 103.4 | J13: 89.89 | K13: 77.29
A14: Cost of debt (Kd) | B14: =B13/B12 -> 0.028610002 | C14: =C13/C12 -> 0.041544872 | D14: =D13/D12 -> 0.055193309 | E14: =E13/E12 -> 0.054637232 | F14: =F13/F12 -> 0.042139343 | G14: =G13/G12 -> 0.039325605 | H14: =H13/H12 -> 0.035056589 | I14: =I13/I12 -> 0.044328788 | ... K14: =K13/K12 -> 0.033303171 | M14: Average Interest Rate | P14: =AVERAGE(B14:K14) -> 0.041235875
A16: Debt | B16: 1585.11 | C16: 1560 | D16: 1171.7 | E16: 1103.46 | F16: 1575.25 | G16: 2122.79 | H16: 3009.42 | I16: 2332.57 | J16: 2351.92 | K16: 2320.8 | M16: Cost of debt, Kd | P16: 0.0412
A17: Equity | B17: 5033.14 | C17: 4355.63 | D17: 4086.69 | E17: 3746.91 | F17: 5568.28 | G17: 9052.54 | H17: 11409.2 | I17: 9879.93 | J17: 12062.61 | K17: 13011.23
M18: Effective Tax Rate is Nil as PSH is tax exempted entity.
A20: Cost of Equity (Capital Asset Pricing Model) | D20: Cost of Equity (Fama French 3 Factor Model) | I20: Weighted Average Cost of Capital
A22: Risk Free Rate | B22: 0.0011743328 | D22: Risk Free Rate | G22: 0.0017500481 | I22: Value of Debt | L22: 2320.8
A23: Market Risk Premium | B23: 0.0070129663 | D23: Market Risk Premium (MRP) | G23: 0.00027285048 | I23: Market Value of Equity | L23: 8904.03
A24: ß(Rm-Rf) | B24: 0.81308247 | D24: Small Minus Big (SMB) | G24: -0.0049719142
D25: High Minus Low (HML) | G25: -0.010532026 | I25: Total Capital | L25: =L22+L23 -> 11224.83
D26: ß(Rm-Rf) | G26: 1.0862394
D27: ßsmb (statistically not significant) | G27: 0 | I27: Weight of Equity | L27: =L23/L25 -> 0.79324408
D28: ßhml | G28: -0.6705656 | I28: Weight of Debt | L28: =L22/L25 -> 0.20675592
I29: Corporate Tax Rate | L29: 0
A30: Monthly ke | B30: =B22+B23*B24 -> 0.0068764527 | D30: Monthly ke | G30: =G22+G23*G26+G24*G27+G25*G28 -> 0.0091088431
A31: Annualised Ke | B31: =(1+B30)^12-1 -> 0.085710936 | D31: Annualised Ke | G31: =(1+G30)^12-1 -> 0.11495193 | I31: Cost of Capital, Ko | L31: =(P16*(1-L29)*L28)+(G31*L27) -> 0.099703284
A34: In estimating Pershing Square Holdings’ weighted average cost of capital (WACC), I apply the Fama–French three‑factor model to derive the cost of equity, which yields an estimate of approximately 11.5% per annum. This approach is consistent with PSH’s concentrated, growth‑tilted portfolio and provides a more robust measure than CAPM alone. For the cost of debt, I use 4.12%, reflecting the yield on PSH’s outstanding long‑term bonds. As PSH is incorporated in Guernsey and exempt from corporate income tax, no tax shield is applied to the cost of debt. These assumptions result in an overall WACC of approximately 9.97%, which is consistent with the risk profile of PSH and comparable listed investment companies.

Sheet Balance Sheet
A1: Company Fundamentals - Balance Sheet
A2: Company Name | B2: Pershing Square Holdings Ltd (PSHP.L)
A3: Standardized Currency | B3: USD | C3: USD | D3: USD | E3: USD | F3: USD | G3: USD | H3: USD | I3: USD | J3: USD | K3: USD
A4: Template Type | B4: Investment Trust - Non-Differentiated | C4: Investment Trust - Non-Differentiated | D4: Investment Trust - Non-Differentiated | E4: Investment Trust - Non-Differentiated | F4: Investment Trust - Non-Differentiated | G4: Investment Trust - Non-Differentiated | H4: Investment Trust - Non-Differentiated | I4: Investment Trust - Non-Differentiated | J4: Investment Trust - Non-Differentiated | K4: Investment Trust - Non-Differentiated
A5: Statement Data | B5: 2015 | C5: 2016 | D5: 2017 | E5: 2018 | F5: 2019 | G5: 2020 | H5: 2021 | I5: 2022 | J5: 2023 | K5: 2024
A6: Field Name
A7: Assets
A8: Cash & Cash Equivalents | B8: 420.41 | C8: 2076.16 | D8: 1082.1 | E8: 201.25 | F8: 1222.85 | G8: 1879.64 | H8: 1767.78 | I8: 1134.16 | J8: 1919.68 | K8: 436.52
A9: Derivative Financial Instruments - Hedging - Total | H9: 843.76 | I9: 704.95 | J9: 274.84 | K9: 51.38
A10: Loans & Receivables - Total | B10: 603.29 | C10: 554.59 | D10: 729.12 | E10: 368.42 | F10: 122.1 | G10: 964.54 | H10: 168.72 | I10: 520.63 | J10: 223.43 | K10: 27.51
A11: Receivables - Other | B11: 603.29 | C11: 554.59 | D11: 729.12 | E11: 368.42 | F11: 122.1 | G11: 964.54 | H11: 168.72 | I11: 520.63 | J11: 223.43 | K11: 27.51
A12: Investments - Total | B12: 5855.6 | C12: 3658.93 | D12: 3885.27 | E12: 4536.95 | F12: 5865.2 | G12: 9697.03 | H12: 13028.11 | I12: 10592.07 | J12: 12710.65 | K12: 15114.61
A13: Investment Securities - Available for Sale, Held to Maturity & Held for Trading - Total | B13: 5855.6 | C13: 3658.93 | D13: 3885.27 | E13: 4536.95 | F13: 5865.2 | G13: 9697.03 | H13: 13028.11 | I13: 10592.07 | J13: 12710.65 | K13: 15114.61
A14: Investment Securities - Held for Trading | B14: 499.39 | C14: 1022.16 | D14: 744.45 | E14: 4536.95 | F14: 5865.2 | G14: 9479.94 | H14: 12494.51 | I14: 10570.57 | J14: 12118.84 | K14: 14561.66
A15: Investment Securities Available for Sale & Held to Maturity | B15: 5356.21 | C15: 2636.77 | D15: 3140.82 | E15: 0 | F15: 0 | G15: 217.09 | H15: 533.6 | I15: 21.5 | J15: 591.81 | K15: 552.94
A16: Investment Securities - Available for Sale - Total | B16: 5356.21 | C16: 2636.77 | D16: 3140.82 | E16: 0 | F16: 0 | G16: 217.09 | H16: 533.6 | I16: 21.5 | J16: 591.81 | K16: 552.94
A17: Other Assets - Total | K17: 2.37
A18: Restricted Accounts - Cash | K18: 1.11
A19: Prepaid Expenses - Total | K19: 1.27
A20: Total Assets
A21: Total Assets | B21: 6879.3 | C21: 6289.68 | D21: 5696.49 | E21: 5106.62 | F21: 7210.14 | G21: 12541.21 | H21: 15808.37 | I21: 12951.81 | J21: 15128.6 | K21: 15632.39
A22: Growth rate | C22: =(C21/B21)-1 -> -0.085709302 | D22: =(D21/C21)-1 -> -0.094311634 | E22: =(E21/D21)-1 -> -0.10354973 | F22: =(F21/E21)-1 -> 0.41192021 | G22: =(G21/F21)-1 -> 0.73938509 | H22: =(H21/G21)-1 -> 0.26051394 | I22: =(I21/H21)-1 -> -0.18069921 | J22: =(J21/I21)-1 -> 0.1680684 | K22: =(K21/J21)-1 -> 0.033300504 | L22: =((K21/B21)^(1/9))-1 -> 0.095491506
A23: Liabilities
A24: Trading Liabilities | B24: 125.97 | C24: 190.73 | D24: 6.19 | E24: 144.7 | F24: 7.61 | G24: 573.59
A25: Debt - Total | B25: 1585.11 | C25: 1560 | D25: 1171.7 | E25: 1103.46 | F25: 1575.25 | G25: 2122.79 | H25: 3009.42 | I25: 2332.57 | J25: 2351.92 | K25: 2320.8
A26: Short-Term Debt & Current Portion of Long-Term Debt | B26: 387.06 | C26: 385.31 | D26: 0 | K26: 71.92
A27: Short-Term Debt & Notes Payable | B27: 387.06 | C27: 385.31 | D27: 0
A28: Collateralized Financing Agreements, REPO Financing Loans - Liabilities | B28: 387.06 | C28: 385.31 | D28: 0
A29: Securities Sold under Repurchase Agreements & Federal Funds Purchased | B29: 387.06 | C29: 385.31 | D29: 0
A30: Securities Sold under Repurchase Agreements | B30: 387.06 | C30: 385.31 | D30: 0
A31: Current Portion of Long-Term Debt including Capitalized Leases | K31: 71.92
A32: Current Portion of Long-Term Debt excluding Capitalized Leases | K32: 71.92
A33: Debt - Long-Term - Total | B33: 1198.06 | C33: 1174.69 | D33: 1171.7 | E33: 1103.46 | F33: 1575.25 | G33: 2122.79 | H33: 3009.42 | I33: 2332.57 | J33: 2351.92 | K33: 2248.88
A34: Long-Term Debt excluding Capitalized Leases | B34: 1014.69 | C34: 1013.55 | D34: 1015.43 | E34: 1017.41 | F34: 1422.88 | G34: 2122.79 | H34: 3009.42 | I34: 2332.57 | J34: 2351.92 | K34: 2248.88
A35: Debt - Non-Convertible - Long-Term | B35: 1014.69 | C35: 1013.55 | D35: 1015.43 | E35: 1017.41 | F35: 1422.88 | G35: 2122.79 | H35: 3009.42 | I35: 2332.57 | J35: 2351.92 | K35: 2248.88
A36: Hybrid Financial Instrument - Liability - Long-Term | B36: 183.37 | C36: 161.14 | D36: 156.27 | E36: 86.05 | F36: 152.36 | G36: 0
A37: Other Mandatorily Redeemable Equity Instruments - Long-Term | B37: 183.37 | C37: 161.14 | D37: 156.27 | E37: 86.05 | F37: 152.36 | G37: 0
A38: Deferred Tax & Investment Tax Credits - Long-Term | F38: 13.51 | G38: 52.45 | H38: 111.54 | I38: 52.22 | J38: 84.83 | K38: 67.89
A39: Deferred Tax - Liability - Long-Term | F39: 13.51 | G39: 52.45 | H39: 111.54 | I39: 52.22 | J39: 84.83 | K39: 67.89
A40: Payables & Accrued Expenses | B40: 135.08 | C40: 183.31 | D40: 431.92 | E40: 111.55 | F40: 45.5 | G40: 739.85 | H40: 1239.37 | I40: 676.85 | J40: 597.28 | K40: 228.06
...

Sheet Income Statement
A1: Company Fundamentals - Income Statement
A2: Company Name | B2: Pershing Square Holdings Ltd (PSHP.L)
A3: Standardized Currency | B3: USD | C3: USD | D3: USD | E3: USD | F3: USD | G3: USD | H3: USD | I3: USD | J3: USD | K3: USD
A4: Template Type | B4: Investment Trust - Non-Differentiated | C4: Investment Trust - Non-Differentiated | D4: Investment Trust - Non-Differentiated | E4: Investment Trust - Non-Differentiated | F4: Investment Trust - Non-Differentiated | G4: Investment Trust - Non-Differentiated | H4: Investment Trust - Non-Differentiated | I4: Investment Trust - Non-Differentiated | J4: Investment Trust - Non-Differentiated | K4: Investment Trust - Non-Differentiated
A5: Statement Data | B5: 2015 | C5: 2016 | D5: 2017 | E5: 2018 | F5: 2019 | G5: 2020 | H5: 2021 | I5: 2022 | J5: 2023 | K5: 2024 | M5: 2025 | N5: 2026 | O5: 2027 | P5: 2028 | Q5: 2029 | R5: 2030
A6: Field Name
A7: Revenues
A8: Investment Income - Gross - Investment | B8: 43.31 | C8: 50.4 | D8: 61.11 | E8: 94.19 | F8: 87.18 | G8: 85.48 | H8: 114.85 | I8: 169.56 | J8: 202.83 | K8: 238.9
A9: Dividend Income - Investments | B9: 43.13 | C9: 49.7 | D9: 59.96 | E9: 89 | F9: 84.15 | G9: 84.42 | H9: 114.73 | I9: 159.24 | J9: 183.12 | K9: 152.93
A10: Interest Income - Investment | B10: 0.18 | C10: 0.62 | D10: 1.14 | E10: 5.17 | F10: 3.03 | G10: 1.06 | H10: 0.12 | I10: 10.28 | J10: 19.71 | K10: 85.94
A11: Investment Income - Other - Total (Investment) | C11: 0.07 | D11: 0.01 | E11: 0.02 | I11: 0.04 | K11: 0.04
A12: Investments & Loans - Business - Gain/(Loss) | B12: -1217.4 | C12: -567.98 | D12: -48.33 | E12: -67.02 | F12: 2272.74 | G12: 4560.31 | H12: 3146.92 | I12: -1104.16 | J12: 2922.19 | K12: 1455.66
A13: Realized Capital Gain/(Loss) - Total | B13: -12.91 | C13: -71.06 | D13: -14.32 | E13: -0.52 | F13: -1.73 | G13: 2057.09 | H13: -109.13 | I13: 2132.75 | J13: -16 | K13: -152.27
A14: Commodities - Realized Gain/(Loss) | B14: -12.91 | C14: -71.06 | D14: -14.32 | E14: -0.52 | F14: -1.73 | G14: 2057.09 | H14: -109.13 | I14: 2132.75 | J14: -16 | K14: -152.27
A15: Capital Gains/(Losses) - Unrealized - Total | B15: 5.52 | C15: -2.68 | D15: 1.27 | E15: 0.75 | G15: -8.91 | H15: 702.99 | I15: -2922.07 | J15: 1395.48 | K15: -13.9
A16: Investment Securities - Unrealized Gain/(Loss) | I16: -2567.58 | J16: 1631.86 | K16: -59.48
A17: Commodities - Unrealized Gain/(Loss) | B17: 5.52 | C17: -2.68 | D17: 1.27 | E17: 0.75 | G17: -8.91 | H17: 692.36 | I17: -388.86 | J17: -219.9 | K17: 11.87
A18: Foreign Exchange Gain/(Loss) - Unrealized - Capital | H18: 10.63 | I18: 34.37 | J18: -16.48 | K18: 33.71
A19: Investment Securities - Business - Gain/(Loss) | I19: -314.84 | J19: 1542.72 | K19: 1621.83
A20: Investments Securities - Available for Sale/Held to Maturity - Realized Gain/(Loss) | I20: -314.84 | J20: 1542.72 | K20: 1621.83
A21: Gain/(Loss) on Sale of Financial Instruments - Other | B21: -1210.01 | C21: -494.23 | D21: -35.28 | E21: -67.25 | F21: 2274.47 | G21: 2512.13 | H21: 2553.06
A22: Revenue from Business Activities - Total | B22: -1174.09 | C22: -517.58 | D22: 12.78 | E22: 27.17 | F22: 2359.92 | G22: 4645.79 | H22: 3261.77 | I22: -934.6 | J22: 3125.03 | K22: 1694.57
A23: Operating Expenses
A24: Cost of Operating Revenue | B24: 17.75 | C24: 10.66 | D24: 11.96 | E24: 6.45 | F24: 7.31 | G24: 9.19 | H24: 8.13 | I24: 9.25 | J24: 13.2 | K24: 10.06
A25: Fees & Commissions Expense | B25: 17.75 | C25: 10.66 | D25: 11.96 | E25: 6.45 | F25: 7.31 | G25: 9.19 | H25: 8.13 | I25: 9.25 | J25: 13.2 | K25: 10.06
A26: Operating Interest Expense - not included within Net Interest Revenue | B26: 45.35 | C26: 64.81 | D26: 64.67 | E26: 60.29 | F26: 66.38 | G26: 83.48 | H26: 105.49 | I26: 103.42
A27: Selling, General & Administrative Expenses - Total | B27: 93.92 | C27: 63.14 | D27: 63.21 | E27: 52.39 | F27: 103.4 | G27: 791.49 | H27: 610.13 | I27: 148.48 | J27: 467.58 | K27: 415.41
A28: Investment Management Fees | B28: 93.92 | C28: 63.14 | D28: 63.21 | E28: 52.39 | F28: 103.4 | G28: 791.49 | H28: 610.13 | I28: 148.48 | J28: 467.58 | K28: 415.41
A29: Investment Management - Base Fees | B29: 93.92 | C29: 63.14 | D29: 63.21 | E29: 52.39 | F29: 64.42 | G29: 95.79 | H29: 146.07 | I29: 148.48 | J29: 155.47 | K29: 188.82
A30: Performance/Incentive Investment Fees | F30: 38.98 | G30: 695.69 | H30: 464.06 | J30: 312.11 | K30: 226.59
A31: Other Operating Expense/(Income) - Net | B31: 1.33 | C31: 1.11 | D31: 3.39 | E31: 1.55 | F31: 1.53 | G31: 2.03 | H31: 2.35 | I31: 2.94 | J31: 2.46 | K31: 3.03
A32: Other Operating Expense | B32: 1.33 | C32: 1.11 | D32: 3.39 | E32: 1.55 | F32: 1.53 | G32: 2.03 | H32: 2.35 | I32: 2.94 | J32: 2.46 | K32: 3.03
A33: Operating Expenses - Total | B33: 113 | C33: 74.91 | D33: 78.57 | E33: 60.4 | F33: 112.24 | G33: 802.7 | H33: 620.61 | I33: 160.67 | J33: 483.23 | K33: 428.49
A34: Operating Profit | B34: =B25+B27+B31 -> 113 | C34: =C25+C27+C31 -> 74.91 | D34: =D25+D27+D31 -> 78.56 | E34: =E25+E27+E31 -> 60.39 | F34: =F25+F27+F31 -> 112.24 | G34: =G25+G27+G31 -> 802.71 | H34: =H25+H27+H31 -> 620.61 | I34: =I25+I27+I31 -> 160.67 | ... K34: =K25+K27+K31 -> 428.5
A35: Operating Profit before Non-Recurring Income/Expense | B35: -1287.09 | C35: -592.49 | D35: -65.79 | E35: -33.23 | F35: 2247.68 | G35: 3843.09 | H35: 2641.16 | I35: -1095.27 | J35: 2641.79 | K35: 1266.07
A36: Non-Operating Expenses
A37: Financing Income/(Expense) - Net - Total | J37: -89.89 | K37: -77.29
A38: Interest Expense - Net of (Interest Income) | J38: 89.89 | K38: 72.11
A39: Interest Expense - Net of Capitalized Interest | J39: 89.89 | K39: 72.11
A40: Non-Interest Financial Income/(Expense) - Total | K40: -5.19
...

Sheet Cash Flow
A1: Company Fundamentals - Income Statement
A2: Company Name | B2: Pershing Square Holdings Ltd (PSHP.L)
A3: Standardized Currency | B3: USD (millions) | C3: USD (millions) | D3: USD (millions) | E3: USD (millions) | F3: USD (millions) | G3: USD (millions) | H3: USD (millions) | I3: USD (millions) | J3: USD (millions) | K3: USD (millions)
A4: Template Type | B4: Investment Trust - Non-Differentiated | C4: Investment Trust - Non-Differentiated | D4: Investment Trust - Non-Differentiated | E4: Investment Trust - Non-Differentiated | F4: Investment Trust - Non-Differentiated | G4: Investment Trust - Non-Differentiated | H4: Investment Trust - Non-Differentiated | I4: Investment Trust - Non-Differentiated | J4: Investment Trust - Non-Differentiated | K4: Investment Trust - Non-Differentiated
A5: Statement Data | B5: 2015 | C5: 2016 | D5: 2017 | E5: 2018 | F5: 2019 | G5: 2020 | H5: 2021 | I5: 2022 | J5: 2023 | K5: 2024
A6: Field Name
A7: Operating Cash Flow - Indirect
A8: Profit/(Loss) - Starting Line - Cash Flow | B8: -1343.86 | C8: -699.74 | D8: -197.49 | E8: -109.14 | F8: 2149.07 | G8: 3698.87 | H8: 2436.31 | I8: -1172.08 | J8: 2486.05 | K8: 1173.7
A9: Non-cash Items & Reconciliation Adjustments - Cash Flow | B9: 24.98 | C9: 55 | D9: -328.44 | E9: 56.98 | F9: 79.27 | G9: 121.02 | H9: 164.49 | I9: -2.32 | J9: 124 | K9: 24.44
A10: Financial Income/(Expense) - Cash Flow - to Reconcile | B10: 29.21 | C10: 56.74 | D10: 56.87 | E10: 56.98 | F10: 65.77 | G10: 82.08 | H10: 103.9 | I10: 91.38 | J10: 74.91 | K10: 75.09
A11: Other Non-Cash Items & Reconciliation Adjustments - Cash Flow - to Reconcile | H11: 1.49 | I11: -34.37 | J11: 16.48 | K11: -33.71
A12: Deferred Income Taxes & Income Tax Credits - Cash Flow - to Reconcile | F12: 13.51 | G12: 38.94 | H12: 59.1 | I12: -59.33 | J12: 32.61 | K12: -16.94
A13: Assets Sale - Gain/(Loss) - Cash Flow - to Reconcile | B13: -4.23 | C13: -1.74 | D13: -385.31
A14: Investment Securities - Gain/(Loss) - Cash Flow | B14: -4.23 | C14: -1.74 | D14: -385.31
A15: Interest Paid - Cash | C15: 57.9 | D15: 55 | E15: 55 | F15: 55 | G15: 74.25 | H15: 101.41 | I15: 103.22 | J15: 72.04 | K15: 72.5
A16: Cash Flow from Operating Activities before Changes in Working Capital | B16: -1318.88 | C16: -702.64 | D16: -580.93 | E16: -107.15 | F16: 2173.35 | G16: 3745.64 | H16: 2499.39 | I16: -1277.62 | J16: 2538.01 | K16: 1125.64
A17: Working Capital - Increase/(Decrease) - Cash Flow | B17: 187.99 | C17: 2358.38 | D17: -338.3 | E17: -472.84 | F17: -1290.55 | G17: -3409.07 | H17: -3413.68 | I17: 1643.66 | J17: -1457.8 | K17: -2391.25
A18: Accounts Receivables - Decrease/(Increase) - Cash Flow | B18: -82.95 | C18: 48.7 | D18: -174.53 | E18: 360.7 | F18: 246.32 | G18: -842.44 | H18: 795.83 | I18: -351.92 | J18: 297.2 | K18: -12.46
A19: Investment Securities - Decrease/(Increase) - Operating - Cash Flow | B19: 434.98 | C19: 2719.44 | D19: -504.05 | E19: -1334.22 | F19: -1259.3 | G19: -3359.13 | H19: -3934.65 | I19: 2449.33 | J19: -2122.62 | K19: -2413.2
A20: Other Assets - Decrease/(Increase) - Cash Flow | B20: -210.27 | C20: -522.78 | D20: 277.71 | E20: 682.54 | F20: -68.95 | G20: -472.7 | H20: -240.2 | I20: 138.81 | J20: 430.11 | K20: 429.48
A21: Accounts Payable - Increase/(Decrease) - Cash Flow | B21: -116.54 | C21: 29.64 | D21: 57.3 | E21: -47.08 | F21: -4.02 | G21: 653.22 | H21: -228.78 | I21: -459.76 | J21: 310.19 | K21: -86.83
A22: Other Liabilities - Increase/(Decrease) -Total - Cash Flow | B22: 162.76 | C22: 83.38 | D22: 5.26 | E22: -134.78 | F22: -204.6 | G22: 611.99 | H22: 194.13 | I22: -132.8 | J22: -372.68 | K22: -308.24
A23: Investing Cash Flow
A24: Net Cash Flow from Operating Activities | B24: -1130.89 | C24: 1655.75 | D24: -919.23 | E24: -580 | F24: 882.79 | G24: 336.58 | H24: -914.29 | I24: 366.04 | J24: 1080.21 | K24: -1265.61
A25: Financing Cash Flow
A26: Dividends Paid - Cash - Total - Cash Flow | F26: 87.75 | G26: 81.14 | H26: 79.65 | I26: 93.27 | J26: 98.78 | K26: 107.17
A27: Dividends - Common - Cash Paid | F27: 87.75 | G27: 81.14 | H27: 79.65 | I27: 93.27 | J27: 98.78 | K27: 107.17
A28: Stock - Total - Issuance/(Retirement) - Net - Cash Flow | D28: -74.83 | E28: -300.86 | F28: -168.31 | G28: -291.18 | H28: 0 | I28: -262.42 | J28: -199.96 | K28: -119.62
A29: Stock - Issuance/(Retirement) - Net - Excluding Options/Warrants - Cash Flow | D29: -74.83 | E29: -300.86 | F29: -168.31 | G29: -291.18 | H29: 0 | I29: -262.42 | J29: -199.96 | K29: -119.62
A30: Stock - Common - Issuance/(Retirement) - Net - Cash Flow | D30: -74.83 | E30: -300.86 | F30: -168.31 | G30: -291.18 | H30: 0 | I30: -262.42 | J30: -199.96 | K30: -119.62
A31: Stock - Common - Issued/Sold - Cash Flow
A32: Stock - Common - Repurchased/Retired - Cash Flow | D32: 74.83 | E32: 300.86 | F32: 168.31 | G32: 291.18 | H32: 0 | I32: 262.42 | J32: 199.96 | K32: 119.62
A33: Debt - Long-Term & Short-Term - Issuance/(Retirement) - Total - Cash Flow | B33: 1000 | F33: 400 | G33: 700 | H33: 907.52 | I33: -630.62
A34: Debt - Issued/(Reduced) - Long-Term & Short-Term - Cash Flow | B34: 1000
A35: Debt - Issued - Long-Term & Short-Term - Cash Flow | B35: 1000
A36: Debt - Issued/(Reduced) - Long-Term - Cash Flow | F36: 400 | G36: 700 | H36: 907.52 | I36: -630.62
A37: Debt - Issued - Long-Term - Cash Flow | F37: 400 | G37: 700 | H37: 1276.89
A38: Debt - Reduced - Long-Term - Cash Flow | H38: 369.38 | I38: 630.62
A39: Other Financing Cash Flow - Increase/(Decrease) | B39: -14.5 | F39: -5.14 | G39: -7.47 | H39: -25.44 | I39: -0.06
A40: Net Cash Flow from Financing Activities | B40: 985.5 | D40: -74.83 | E40: -300.86 | F40: 138.81 | G40: 320.22 | H40: 802.43 | I40: -986.37 | J40: -298.74 | K40: -226.79
...

Sheet Dividends
A1: Pershing Square Holdings Ltd (PSHP.L)
B4: Dividend List as per PSH website | G4: Forecast Dividend
A6: Year | B6: Total DPS | F6: Year | G6: Total DPS
A7: 2019 | B7: 0.4 | F7: 2026 | G7: =_xlfn.FORECAST.ETS(F7,$B$7:$B$13,$A$7:$A$13) -> 0.70023735 | H7: =LN(G7/B13) -> 0.061606705
A8: 2020 | B8: 0.4 | C8: =LN(B8/B7) -> 0 | F8: 2027 | G8: =_xlfn.FORECAST.ETS(F8,$B$7:$B$13,$A$7:$A$13) -> 0.74532055 | H8: =LN(G8/G7) -> 0.062395041
A9: 2021 | B9: 0.4 | C9: =LN(B9/B8) -> 0 | F9: 2028 | G9: =_xlfn.FORECAST.ETS(F9,$B$7:$B$13,$A$7:$A$13) -> 0.79040375 | H9: =LN(G9/G8) -> 0.058729493
A10: 2022 | B10: 0.475 | C10: =LN(B10/B9) -> 0.17185026 | F10: 2029 | G10: =_xlfn.FORECAST.ETS(F10,$B$7:$B$13,$A$7:$A$13) -> 0.83548694 | H10: =LN(G10/G9) -> 0.055470834
A11: 2023 | B11: 0.5228 | C11: =LN(B11/B10) -> 0.095884178 | F11: 2030 | G11: =_xlfn.FORECAST.ETS(F11,$B$7:$B$13,$A$7:$A$13) -> 0.88057014 | H11: =LN(G11/G10) -> 0.052554864
A12: 2024 | B12: 0.5824 | C12: =LN(B12/B11) -> 0.10795852 | F12: 2031 | G12: =_xlfn.FORECAST.ETS(F12,$B$7:$B$13,$A$7:$A$13) -> 0.92565334 | H12: =LN(G12/G11) -> 0.049930214
A13: 2025 | B13: 0.6584 | C13: =LN(B13/B12) -> 0.12265515 | F13: 2032 | G13: =_xlfn.FORECAST.ETS(F13,$B$7:$B$13,$A$7:$A$13) -> 0.97073653 | H13: =LN(G13/G12) -> 0.047555298
B16: 2015 | C16: 2016 | D16: 2017 | E16: 2018 | F16: 2019 | G16: 2020 | H16: 2021 | I16: 2022 | J16: 2023 | K16: 2024
A17: EPS | B17: -0.25 | C17: -0.13 | D17: -0.81 | E17: -0.43 | F17: 9.78 | G17: 18.12 | H17: 12.36 | I17: -5.96 | J17: 13.17 | K17: 6.38
A18: DPS | E18: 0.4 | F18: 0.4 | G18: 0.4 | H18: 0.475 | I18: 0.5228 | J18: 0.5824 | K18: 0.6584
A19: payout | F19: =F18/F17 -> 0.040899796 | G19: =G18/G17 -> 0.022075055 | H19: =H18/H17 -> 0.038430421 | J19: =J18/J17 -> 0.044221716 | K19: =K18/K17 -> 0.10319749 | M19: Median | N19: =MEDIAN(F19:K19) -> 0.040899796

Sheet Calculations
A1: Pershing Square Holdings Ltd (PSHP.L)
A3: Pershing Square Holdings Ltd (PSHP.L) is a investment company and includes both gains and losses from sale of financial assets as revenue. Hence Revenue cannot be used to calculate growth rate
A4: Hence we are using Book Value per share
A6: Statement Data | B6: 2015 | C6: 2016 | D6: 2017 | E6: 2018 | F6: 2019 | G6: 2020 | H6: 2021 | I6: 2022 | J6: 2023 | K6: 2024
A7: Shareholders' Equity - Attributable to Parent Shareholders - Total | B7: 5033.14 | C7: 4355.63 | D7: 4086.69 | E7: 3746.91 | F7: 5568.28 | G7: 9052.54 | H7: 11409.2 | I7: 9879.93 | J7: 12062.61 | K7: 13011.23
A8: Common Shares - Outstanding - Total | B8: 5248.63 | C8: 5248.63 | D8: 243.22 | E8: 221.24 | F8: 211.84 | G8: 199.12 | H8: 199.12 | I8: 190.86 | J8: 185.46 | K8: 182.96
A9: BV per share | B9: =B7/B8 -> 0.95894357 | C9: =C7/C8 -> 0.82986036 | D9: =D7/D8 -> 16.802442 | E9: =E7/E8 -> 16.935952 | F9: =F7/F8 -> 26.28531 | G9: =G7/G8 -> 45.462736 | H9: =H7/H8 -> 57.298112 | I9: =I7/I8 -> 51.765325 | ... K9: =K7/K8 -> 71.115162
A11: Revenue from Business Activities - Total | B11: -1174.09 | C11: -517.58 | D11: 12.78 | E11: 27.17 | F11: 2359.92 | G11: 4645.79 | H11: 3261.77 | I11: -934.6 | J11: 3125.03 | K11: 1694.57
A12: Operating Profit before Non-Recurring Income/Expense | B12: -1287.09 | C12: -592.49 | D12: -65.79 | E12: -33.23 | F12: 2247.68 | G12: 3843.09 | H12: 2641.16 | I12: -1095.27 | J12: 2641.79 | K12: 1266.07
A13: Gross Profit Magin | B13: =B12/B11 -> 1.0962448 | C13: =C12/C11 -> 1.1447312 | D13: =D12/D11 -> -5.1478873 | E13: =E12/E11 -> -1.2230401 | F13: =F12/F11 -> 0.95243907 | G13: =G12/G11 -> 0.82721991 | H13: =H12/H11 -> 0.80973214 | I13: =I12/I11 -> 1.1719131 | ... K13: =K12/K11 -> 0.74713349
A15: Income Available to Common Shares | B15: -1300.01 | C15: -677.51 | D15: -192.62 | E15: -91.51 | F15: 2097.64 | G15: 3571.84 | H15: 2436.31 | I15: -1172.08 | J15: 2486.05 | K15: 1173.7
A16: Net Profit Margin | B16: =B15/B11 -> 1.107249 | C16: =C15/C11 -> 1.3089957 | D16: =D15/D11 -> -15.071987 | E16: =E15/E11 -> -3.368053 | F16: =F15/F11 -> 0.88886064 | G16: =G15/G11 -> 0.76883372 | H16: =H15/H11 -> 0.74692881 | I16: =I15/I11 -> 1.254098 | ... K16: =K15/K11 -> 0.69262409
A18: Shareholders' Equity - Attributable to Parent Shareholders - Total | B18: 5033.14 | C18: 4355.63 | D18: 4086.69 | E18: 3746.91 | F18: 5568.28 | G18: 9052.54 | H18: 11409.2 | I18: 9879.93 | J18: 12062.61 | K18: 13011.23
A19: ROE | B19: =B15/B18 -> -0.25829005 | C19: =C15/C18 -> -0.15554811 | D19: =D15/D18 -> -0.047133499 | E19: =E15/E18 -> -0.024422791 | F19: =F15/F18 -> 0.37671238 | G19: =G15/G18 -> 0.39456771 | H19: =H15/H18 -> 0.21353907 | I19: =I15/I18 -> -0.11863242 | ... K19: =K15/K18 -> 0.090206691 | M19: Average | N19: =AVERAGE(B19:K19) -> 0.067709451
A22: Total Debt (millions USD) | B22: 1585.11 | C22: 1560 | D22: 1171.7 | E22: 1103.46 | F22: 1575.25 | G22: 2122.79 | H22: 3009.42 | I22: 2332.57 | J22: 2351.92 | K22: 2320.8
A23: Interest expense | B23: 45.35 | C23: 64.81 | D23: 64.67 | E23: 60.29 | F23: 66.38 | G23: 83.48 | H23: 105.5 | I23: 103.4 | J23: 89.89 | K23: 77.29
A24: Cost of debt (Kd) | B24: =B23/B22 -> 0.028610002 | C24: =C23/C22 -> 0.041544872 | D24: =D23/D22 -> 0.055193309 | E24: =E23/E22 -> 0.054637232 | F24: =F23/F22 -> 0.042139343 | G24: =G23/G22 -> 0.039325605 | H24: =H23/H22 -> 0.035056589 | I24: =I23/I22 -> 0.044328788 | ... K24: =K23/K22 -> 0.033303171 | M24: Average Interest Rate | P24: =AVERAGE(B24:K24) -> 0.041235875
A27: EPS | B27: -0.25 | C27: -0.13 | D27: -0.81 | E27: -0.43 | F27: 9.78 | G27: 18.12 | H27: 12.36 | I27: -5.96 | J27: 13.17 | K27: 6.38
A28: DPS | E28: 0.4 | F28: 0.4 | G28: 0.4 | H28: 0.475 | I28: 0.5228 | J28: 0.5824 | K28: 0.6584
A29: payout | F29: =F28/F27 -> 0.040899796 | G29: =G28/G27 -> 0.022075055 | H29: =H28/H27 -> 0.038430421 | J29: =J28/J27 -> 0.044221716 | K29: =K28/K27 -> 0.10319749 | M29: median | N29: =MEDIAN(E29:K29) -> 0.040899796

Sheet EBIT
A1: Company Fundamentals - Income Statement
A2: Company Name | B2: Pershing Square Holdings Ltd (PSHP.L)
A3: Standardized Currency | B3: USD | C3: USD | D3: USD | E3: USD | F3: USD | G3: USD | H3: USD | I3: USD | J3: USD | K3: USD
A4: Template Type | B4: Investment Trust - Non-Differentiated | C4: Investment Trust - Non-Differentiated | D4: Investment Trust - Non-Differentiated | E4: Investment Trust - Non-Differentiated | F4: Investment Trust - Non-Differentiated | G4: Investment Trust - Non-Differentiated | H4: Investment Trust - Non-Differentiated | I4: Investment Trust - Non-Differentiated | J4: Investment Trust - Non-Differentiated | K4: Investment Trust - Non-Differentiated
A5: Statement Data | B5: 2015 | C5: 2016 | D5: 2017 | E5: 2018 | F5: 2019 | G5: 2020 | H5: 2021 | I5: 2022 | J5: 2023 | K5: 2024
A6: Earnings | B6: -1174.09 | C6: -517.58 | D6: 12.78 | E6: 27.17 | F6: 2359.92 | G6: 4645.79 | H6: 3261.77 | I6: -934.6 | J6: 3125.03 | K6: 1694.57
A7: Operating Expenses | B7: 113 | C7: 74.91 | D7: 78.57 | E7: 60.4 | F7: 112.24 | G7: 802.7 | H7: 620.61 | I7: 160.67 | J7: 483.23 | K7: 428.49
A8: EBIT | B8: =B6-B7 -> -1287.09 | C8: =C6-C7 -> -592.49 | D8: =D6-D7 -> -65.79 | E8: =E6-E7 -> -33.23 | F8: =F6-F7 -> 2247.68 | G8: =G6-G7 -> 3843.09 | H8: =H6-H7 -> 2641.16 | I8: =I6-I7 -> -1095.27 | ... K8: =K6-K7 -> 1266.08
A9: Interest | B9: 45.35 | C9: 64.81 | D9: 64.67 | E9: 60.29 | F9: 66.38 | G9: 83.48 | H9: 105.49 | I9: 103.42 | J9: 89.89 | K9: 77.29
A10: EBT | B10: =B8-B9 -> -1332.44 | C10: =C8-C9 -> -657.3 | D10: =D8-D9 -> -130.46 | E10: =E8-E9 -> -93.52 | F10: =F8-F9 -> 2181.3 | G10: =G8-G9 -> 3759.61 | H10: =H8-H9 -> 2535.67 | I10: =I8-I9 -> -1198.69 | ... K10: =K8-K9 -> 1188.79
A13: NOPAT = EBIT (1- tax) | B13: =B8*(1-0) -> -1287.09 | C13: =C8*(1-0) -> -592.49 | D13: =D8*(1-0) -> -65.79 | E13: =E8*(1-0) -> -33.23 | F13: =F8*(1-0) -> 2247.68 | G13: =G8*(1-0) -> 3843.09 | H13: =H8*(1-0) -> 2641.16 | I13: =I8*(1-0) -> -1095.27 | ... K13: =K8*(1-0) -> 1266.08
A22: * Corporate Tax is 0% as PSH is exempted.
A23: *** Non Recurring items like Litigation expenses and Early Extinguishment of Lease Related Debts are not included

Sheet DDM
A1: Pershing Square Holdings Ltd (PSHP.L) Dividend Discount Model
B3: GDP growth forecast for the UK as per HM Treasury September, 2025 is 3.6% (pg 8, table 5). (https://assets.publishing.service.gov.uk/media/68ca721e1eabc899da708491/Forecomp_September.pdf)
B4: GDP growth forecast for the USA as per the Congressional Budget Office Projections is 4% (Table 1). (https://www.cbo.gov/publication/61738#_idTextAnchor000)
B5: As PSHP.L is listed on the London Stock Exchange, its portfolio is almost entirely composed of large‑capitalisation U.S. companies. As such, the long‑term growth assumptions underpinning NAV‑based valuation models are anchored to U.S. nominal GDP growth, which more accurately reflects the operating environment and earnings trajectory of the underlying holdings. However, in the context of UK listing, where investment sentiment matters, UK nominal GDP growth is used.
B7: DPS (declared divident for Dec, 2025) | C7: 0.6584
B8: EPS | C8: 6.38
B9: payout ratio | C9: =Calculations!$N$29 -> 0.040899796
B10: retention ratio | C10: =1-C9 -> 0.9591002
B11: ROE | C11: =Calculations!$N$19 -> 0.067709451
B12: growth rate | C12: =C11*C10 -> 0.064940149
B13: long term growth (USA) | C13: 0.04 | E13: this is as per the US Congressional budget office estimate of the economy from 2025 to 2028 Economic Projections Table 1
B14: long term growth (UK) | C14: 0.036 | E14: this is as per the nominal GDP forecast by Office for Budget Responsibility as stated in HM Treasury September, 2025 forecast- pg 8, table 5
B15: total outstanding shares | C15: =183*1000000 -> 183000000
B17: We will be using long term growth rate for to forecast dividend and US based long term growth rate to forecast performance metrics like Net Profit and Cash Flows
B21: Scenario 1: 5 years high growth rate and then normal long term growth, Ke from CAPM | H21: Scenario 3: 5 years exponential forecasted growth and then normal long term growth, Ke from CAPM
B23: Year (T0= 2025) | C23: dividends | D23: growth | E23: Ke | F23: PV | H23: Year (T0= 2025) | I23: dividends | J23: growth | K23: Ke | L23: PV
B24: 2025 | C24: =$C$7 -> 0.6584 | H24: 2025 | I24: =Dividends!B13 -> 0.6584
B25: 2026 | C25: =$C$24*(1+$C$12)^(B25-$B$24) -> 0.70115659 | D25: 0.0649 | E25: =WACC!$B$31 -> 0.085710936 | F25: =C25/(1+$E25)^(B25-$B$24) -> 0.64580412 | H25: 2026 | I25: =Dividends!G7 -> 0.70023735 | K25: =WACC!$B$31 -> 0.085710936 | L25: =I25/(1+$K25)^(H25-$H$24) -> 0.64495745
B26: 2027 | C26: =$C$24*(1+$C$12)^(B26-$B$24) -> 0.74668981 | D26: 0.0649 | E26: =WACC!$B$31 -> 0.085710936 | F26: =C26/(1+$E26)^(B26-$B$24) -> 0.63344921 | H26: 2027 | I26: =Dividends!G8 -> 0.74532055 | K26: =WACC!$B$31 -> 0.085710936 | L26: =I26/(1+$K26)^(H26-$H$24) -> 0.63228761
B27: 2028 | C27: =$C$24*(1+$C$12)^(B27-$B$24) -> 0.79517995 | D27: 0.0649 | E27: =WACC!$B$31 -> 0.085710936 | F27: =C27/(1+$E27)^(B27-$B$24) -> 0.62133066 | H27: 2028 | I27: =Dividends!G9 -> 0.79040375 | K27: =WACC!$B$31 -> 0.085710936 | L27: =I27/(1+$K27)^(H27-$H$24) -> 0.61759867
B28: 2029 | C28: =$C$24*(1+$C$12)^(B28-$B$24) -> 0.84681906 | D28: 0.0649 | E28: =WACC!$B$31 -> 0.085710936 | F28: =C28/(1+$E28)^(B28-$B$24) -> 0.60944396 | H28: 2029 | I28: =Dividends!G10 -> 0.83548694 | K28: =WACC!$B$31 -> 0.085710936 | L28: =I28/(1+$K28)^(H28-$H$24) -> 0.60128839
B29: 2030 | C29: =$C$24*(1+$C$12)^(B29-$B$24) -> 0.90181161 | D29: 0.0649 | E29: =WACC!$B$31 -> 0.085710936 | F29: =C29/(1+$E29)^(B29-$B$24) -> 0.59778465 | H29: 2030 | I29: =Dividends!G11 -> 0.88057014 | K29: =WACC!$B$31 -> 0.085710936 | L29: =I29/(1+$K29)^(H29-$H$24) -> 0.5837043
B30: Terminal | C30: =C29*(1+D30)/(E30-D30) -> 18.794191 | D30: =C14 -> 0.036 | E30: =WACC!$B$31 -> 0.085710936 | F30: =C30/(1+$E30)^(B29-$B$24) -> 12.458122 | H30: Terminal | I30: =I29*(1+J30)/(K30-J30) -> 18.351508 | J30: =$C$14 -> 0.036 | K30: =WACC!$B$31 -> 0.085710936 | L30: =I30/(1+$K30)^(H29-$H$24) -> 12.16468
B31: PSH Valuation per share as per CAPM | F31: =SUM(F25:F30) -> 15.565934 | H31: PSH Valuation per share as per CAPM | L31: =SUM(L25:L30) -> 15.244517
B35: Scenario 2: 5 years high growth rate and then normal long term growth, Ke from French Fama 3 Model | H35: Scenario 4: 5 years exponential forecasted growth and then normal long term growth, Ke from CAPM
B37: Year (T0= 2025) | C37: dividends | D37: growth | E37: Ke | F37: PV | H37: Year (T0= 2025) | I37: dividends | J37: growth | K37: Ke | L37: PV
B38: 2025 | C38: =$C$7 -> 0.6584 | H38: 2025 | I38: =Dividends!B13 -> 0.6584
B39: 2026 | C39: =$C$24*(1+$C$12)^(B39-$B$24) -> 0.70115659 | D39: 0.0649 | E39: =WACC!$G$31 -> 0.11495193 | F39: =C39/(1+$E39)^(B39-$B$38) -> 0.62886711 | H39: 2026 | I39: =Dividends!G7 -> 0.70023735 | K39: =WACC!G$31 -> 0.11495193 | L39: =I39/(1+$K39)^(H39-$H$38) -> 0.62804264
